<?xml version="1.0" ?>
<!-- =================================================================================== -->
<!-- |    This document was autogenerated by xacro from ./urdf_sim/robot_gazebo.urdf.xacro | -->
<!-- |    EDITING THIS FILE BY HAND IS NOT RECOMMENDED                                 | -->
<!-- =================================================================================== -->
<robot name="ginko" xmlns:xacro="http://www.ros.org/wiki/xacro">
  <!-- Used for fixing robot to Gazebo 'base_link' -->
  <!-- <link name="base"/> -->
  <gazebo>
    <plugin filename="libgazebo_ros_control.so" name="gazebo_ros_control">
      <robotNamespace>/ginko</robotNamespace>
      <robotSimType>gazebo_ros_control/DefaultRobotHWSim</robotSimType>
    </plugin>
  </gazebo>

  <link name="base_link"/>
  <joint name="base_joint" type="fixed">
    <parent link="base_link"/>
    <child link="body_link0"/>
    <origin rpy="0 0 0" xyz="0 0 0"/>
    <axis xyz="0 0 1"/>
    <limit effort="0.0" lower="0.0" upper="0.0" velocity="0.0"/>
  </joint>
  <!-- chest -->
  <link name="body_link0">
    <collision>
      <origin rpy="0 0 0" xyz="0 0 0"/>
      <geometry>
        <mesh filename="package://ginko_description/meshes/stl/link00_chest.stl"/>
      </geometry>
    </collision>
    <visual>
      <origin rpy="0 0 0" xyz="0 0 0"/>
      <geometry>
        <mesh filename="package://ginko_description/meshes/stl/link00_chest.stl"/>
      </geometry>
    </visual>
    <inertial>
      <mass value="1.41502697"/>
      <origin rpy="0 0 0" xyz="0.00008301 0.00000908 0.03819562"/>
      <inertia ixx="0.00248548" ixy="-0.00000074" ixz="0.000003761" iyy="0.00121388" iyz="-0.00000042" izz="0.00287756"/>
    </inertial>
  </link>

  <!-- waist -->
  <link name="body_link1">
    <collision>
      <origin rpy="0 0 0" xyz="0 0 0"/>
      <geometry>
        <mesh filename="package://ginko_description/meshes/stl/link01_waist.stl"/>
      </geometry>
    </collision>
    <visual>
      <origin rpy="0 0 0" xyz="0 0 0"/>
      <geometry>
        <mesh filename="package://ginko_description/meshes/stl/link01_waist.stl"/>
      </geometry>
    </visual>
    <inertial>
      <mass value="0.33312665"/>
      <origin rpy="0 0 0" xyz="-0.01135452 -0.00000134 -0.02720222"/>
      <inertia ixx="0.00015328" ixy="0.00000003" ixz="0.00001078" iyy="0.00073745" iyz="0.00000000" izz="0.00073107"/>
    </inertial>
  </link>
  <joint name="body_joint1" type="revolute">
    <parent link="body_link0"/>
    <child link="body_link1"/>
    <origin rpy="0 0 0" xyz="0 0 0"/>
    <axis xyz="0 0 1"/>
    <limit effort="100.0" lower="-2.6" upper="2.6" velocity="10.0"/>
  </joint>
  <!-- chest -->
  <gazebo reference="body_link0">
    <kp>10000.0</kp>
    <kd>0.0</kd>
    <mu1>1.0</mu1>
    <maxVel>1.0</maxVel>
    <minDepth>0.0001</minDepth>
    <maxContacts>5</maxContacts>
    <selfCollide>false</selfCollide>
    <!-- <dampingFactor>0.01</dampingFactor> -->
  </gazebo>
  <transmission name="body_tran0">
    <type>transmission_interface/SimpleTransmission</type>
    <joint name="body_joint1">
      <hardwareInterface>hardware_interface/EffortJointInterface</hardwareInterface>
    </joint>
    <actuator name="body_motor0">
      <hardwareInterface>hardware_interface/EffortJointInterface</hardwareInterface>
      <mechanicalReduction>1</mechanicalReduction>
    </actuator>
  </transmission>
  <!-- waist -->
  <gazebo reference="body_link1">
    <kp>10000.0</kp>
    <kd>0.0</kd>
    <mu1>1.0</mu1>
    <maxVel>1.0</maxVel>
    <minDepth>0.0001</minDepth>
    <maxContacts>5</maxContacts>
    <selfCollide>false</selfCollide>
    <!-- <dampingFactor>0.01</dampingFactor> -->
  </gazebo>
  <!-- shoulder pitch. -->
  <link name="arm_l_link0">
    <collision>
      <origin rpy="0 0 0" xyz="0 0 0"/>
      <geometry>
        <mesh filename="package://ginko_description/meshes/stl/link09_l_arm01.stl"/>
      </geometry>
    </collision>
    <visual>
      <origin rpy="0 0 0" xyz="0 0 0"/>
      <geometry>
        <mesh filename="package://ginko_description/meshes/stl/link09_l_arm01.stl"/>
      </geometry>
    </visual>
    <inertial>
      <mass value="0.01356014"/>
      <origin rpy="0 0 0" xyz="-0.01125790 0.00529265 0.00000000"/>
      <inertia ixx="0.00000235" ixy="0.00000004" ixz="0.00000000" iyy="0.00001670" iyz="0.00000000" izz="0.00001606"/>
    </inertial>
  </link>
  <joint name="arm_l_joint0" type="revolute">
    <parent link="body_link0"/>
    <child link="arm_l_link0"/>
    <origin rpy="0 0.3927 0" xyz="0 0.10683 0.05115"/>
    <axis xyz="0 -1 0"/>
    <limit effort="100.0" lower="-2.6" upper="2.6" velocity="10.0"/>
  </joint>
  <!-- shoulder roll -->
  <link name="arm_l_link1">
    <collision>
      <origin rpy="0 0 0" xyz="0 0 0"/>
      <geometry>
        <mesh filename="package://ginko_description/meshes/stl/link10_l_arm02.stl"/>
      </geometry>
    </collision>
    <visual>
      <origin rpy="0 0 0" xyz="0 0 0"/>
      <geometry>
        <mesh filename="package://ginko_description/meshes/stl/link10_l_arm02.stl"/>
      </geometry>
    </visual>
    <inertial>
      <mass value="0.33139947"/>
      <origin rpy="0 0 0" xyz="-0.02612786 0.02650564 -0.06333369"/>
      <inertia ixx="0.00115128" ixy="0.00015366" ixz="-0.00031848" iyy="0.00113572" iyz="-0.00037104" izz="0.00064743"/>
    </inertial>
  </link>
  <joint name="arm_l_joint1" type="revolute">
    <parent link="arm_l_link0"/>
    <child link="arm_l_link1"/>
    <origin rpy="1.1781 0 0" xyz="0.035 0.0246 0"/>
    <axis xyz="1 0 0"/>
    <limit effort="100.0" lower="-0.85" upper="1.18" velocity="10.0"/>
  </joint>
  <!-- scissors -->
  <link name="arm_l_link2">
    <collision>
      <origin rpy="0 0 0" xyz="0 0 0"/>
      <geometry>
        <mesh filename="package://ginko_description/meshes/stl/link11_l_scissor01.stl"/>
      </geometry>
    </collision>
    <visual>
      <origin rpy="0 0 0" xyz="0 0 0"/>
      <geometry>
        <mesh filename="package://ginko_description/meshes/stl/link11_l_scissor01.stl"/>
      </geometry>
    </visual>
    <inertial>
      <mass value="0.03287850"/>
      <origin rpy="0 0 0" xyz="0.08234859 -0.030246866 0.00514112"/>
      <inertia ixx="0.00002277" ixy="-0.00000014" ixz="-0.00000058" iyy="0.00008197" iyz="-0.00000001" izz="0.00010105"/>
    </inertial>
  </link>
  <joint name="arm_l_joint2" type="revolute">
    <parent link="arm_l_link1"/>
    <child link="arm_l_link2"/>
    <origin rpy="0 0.7854 0" xyz="0.0092 0.0547 -0.11295"/>
    <axis xyz="0 1 0"/>
    <limit effort="100.0" lower="-2.36" upper="2.36" velocity="10.0"/>
  </joint>
  <link name="arm_l_link3">
    <collision>
      <origin rpy="0 0 0" xyz="0 0 0"/>
      <geometry>
        <mesh filename="package://ginko_description/meshes/stl/link12_l_scissor02.stl"/>
      </geometry>
    </collision>
    <visual>
      <origin rpy="0 0 0" xyz="0 0 0"/>
      <geometry>
        <mesh filename="package://ginko_description/meshes/stl/link12_l_scissor02.stl"/>
      </geometry>
    </visual>
    <inertial>
      <mass value="0.02936110"/>
      <origin rpy="0 0 0" xyz="0.07807033 0.02515230 -0.00665437"/>
      <inertia ixx="0.00001452" ixy="0.00000023" ixz="-0.00000245" iyy="0.00006407" iyz="-0.00000002" izz="0.00008024"/>
    </inertial>
  </link>
  <joint name="arm_l_joint3" type="revolute">
    <parent link="arm_l_link1"/>
    <child link="arm_l_link3"/>
    <origin rpy="0 0.7854 0" xyz="0.0092 -0.0018 -0.11295"/>
    <axis xyz="0 1 0"/>
    <limit effort="100.0" lower="-2.36" upper="2.36" velocity="10.0"/>
  </joint>
  <!-- LiDAR -->
  <link name="arm_l_urg_link">
    <collision>
      <origin rpy="0 0 0" xyz="0 0 0"/>
      <geometry>
        <mesh filename="package://ginko_description/meshes/stl/urg.stl"/>
      </geometry>
    </collision>
    <visual>
      <origin rpy="0 0 0" xyz="0 0 0"/>
      <geometry>
        <mesh filename="package://ginko_description/meshes/stl/urg.stl"/>
      </geometry>
    </visual>
    <inertial>
      <mass value="0.16705492"/>
      <origin rpy="0 0 0" xyz="-0.00014579 0.00000831 -0.02360505"/>
      <inertia ixx="0.00008801" ixy="0.00000000" ixz="-0.00000049" iyy="0.00008854" iyz="-0.00000004" izz="0.00006019"/>
    </inertial>
  </link>
  <!-- use zero-limited revolute joint for fixed joint (SDF) -->
  <joint name="arm_l_urg_joint" type="fixed">
    <parent link="arm_l_link1"/>
    <child link="arm_l_urg_link"/>
    <origin rpy="0 1.57 -1.57" xyz="-0.0456 -0.01715 -0.06795"/>
    <axis xyz="0 0 1"/>
    <limit effort="0.0" lower="0.0" upper="0.0" velocity="0.0"/>
  </joint>
  <!-- shoulder pitch. -->
  <gazebo reference="arm_l_link0">
    <kp>10000.0</kp>
    <kd>0.0</kd>
    <mu1>1.0</mu1>
    <maxVel>1.0</maxVel>
    <minDepth>0.0001</minDepth>
    <maxContacts>5</maxContacts>
    <selfCollide>false</selfCollide>
    <!-- <dampingFactor>0.01</dampingFactor> -->
  </gazebo>
  <!-- shoulder roll -->
  <gazebo reference="arm_l_link1">
    <kp>10000.0</kp>
    <kd>0.0</kd>
    <mu1>1.0</mu1>
    <maxVel>1.0</maxVel>
    <minDepth>0.0001</minDepth>
    <maxContacts>5</maxContacts>
    <selfCollide>false</selfCollide>
    <!-- <dampingFactor>0.01</dampingFactor> -->
  </gazebo>
  <!-- scissors -->
  <gazebo reference="arm_l_link2">
    <kp>10000.0</kp>
    <kd>0.0</kd>
    <mu1>1.0</mu1>
    <maxVel>1.0</maxVel>
    <minDepth>0.0001</minDepth>
    <maxContacts>5</maxContacts>
    <selfCollide>false</selfCollide>
    <!-- <dampingFactor>0.01</dampingFactor> -->
  </gazebo>
  <gazebo reference="arm_l_link3">
    <kp>10000.0</kp>
    <kd>0.0</kd>
    <mu1>1.0</mu1>
    <maxVel>1.0</maxVel>
    <minDepth>0.0001</minDepth>
    <maxContacts>5</maxContacts>
    <selfCollide>false</selfCollide>
    <!-- <dampingFactor>0.01</dampingFactor> -->
  </gazebo>
  <transmission name="arm_l_tran0">
    <type>transmission_interface/SimpleTransmission</type>
    <joint name="arm_l_joint0">
      <hardwareInterface>hardware_interface/EffortJointInterface</hardwareInterface>
    </joint>
    <actuator name="arm_l_motor0">
      <hardwareInterface>hardware_interface/EffortJointInterface</hardwareInterface>
      <mechanicalReduction>1</mechanicalReduction>
    </actuator>
  </transmission>
  <transmission name="arm_l_tran1">
    <type>transmission_interface/SimpleTransmission</type>
    <joint name="arm_l_joint1">
      <hardwareInterface>hardware_interface/EffortJointInterface</hardwareInterface>
    </joint>
    <actuator name="arm_l_motor1">
      <hardwareInterface>hardware_interface/EffortJointInterface</hardwareInterface>
      <mechanicalReduction>1</mechanicalReduction>
    </actuator>
  </transmission>
  <transmission name="arm_l_tran2">
    <type>transmission_interface/SimpleTransmission</type>
    <joint name="arm_l_joint2">
      <hardwareInterface>hardware_interface/EffortJointInterface</hardwareInterface>
    </joint>
    <actuator name="arm_l_motor2">
      <hardwareInterface>hardware_interface/EffortJointInterface</hardwareInterface>
      <mechanicalReduction>1</mechanicalReduction>
    </actuator>
  </transmission>
  <transmission name="arm_l_tran3">
    <type>transmission_interface/SimpleTransmission</type>
    <joint name="arm_l_joint3">
      <hardwareInterface>hardware_interface/EffortJointInterface</hardwareInterface>
    </joint>
    <actuator name="arm_l_motor3">
      <hardwareInterface>hardware_interface/EffortJointInterface</hardwareInterface>
      <mechanicalReduction>1</mechanicalReduction>
    </actuator>
  </transmission>
  <!-- shoulder pitch. -->
  <link name="arm_r_link0">
    <collision>
      <origin rpy="0 0 0" xyz="0 0 0"/>
      <geometry>
        <mesh filename="package://ginko_description/meshes/stl/link09_r_arm01.stl"/>
      </geometry>
    </collision>
    <visual>
      <origin rpy="0 0 0" xyz="0 0 0"/>
      <geometry>
        <mesh filename="package://ginko_description/meshes/stl/link09_r_arm01.stl"/>
      </geometry>
    </visual>
    <inertial>
      <mass value="0.01356014"/>
      <origin rpy="0 0 0" xyz="-0.01125790 -0.00529265 0.00000000"/>
      <inertia ixx="0.00000235" ixy="-0.00000004" ixz="0.00000000" iyy="0.00001670" iyz="0.00000000" izz="0.00001606"/>
    </inertial>
  </link>
  <joint name="arm_r_joint0" type="revolute">
    <parent link="body_link0"/>
    <child link="arm_r_link0"/>
    <origin rpy="0 0.3927 0" xyz="0 -0.10683 0.05115"/>
    <axis xyz="0 1 0"/>
    <limit effort="100.0" lower="-2.6" upper="2.6" velocity="10.0"/>
  </joint>
  <!-- shoulder roll -->
  <link name="arm_r_link1">
    <collision>
      <origin rpy="0 0 0" xyz="0 0 0"/>
      <geometry>
        <mesh filename="package://ginko_description/meshes/stl/link10_r_arm02.stl"/>
      </geometry>
    </collision>
    <visual>
      <origin rpy="0 0 0" xyz="0 0 0"/>
      <geometry>
        <mesh filename="package://ginko_description/meshes/stl/link10_r_arm02.stl"/>
      </geometry>
    </visual>
    <inertial>
      <mass value="0.33139947"/>
      <origin rpy="0 0 0" xyz="-0.02612786 -0.02650564 -0.06333369"/>
      <inertia ixx="0.00115128" ixy="-0.00015366" ixz="-0.00031848" iyy="0.00113572" iyz="0.00037104" izz="0.00064743"/>
    </inertial>
  </link>
  <joint name="arm_r_joint1" type="revolute">
    <parent link="arm_r_link0"/>
    <child link="arm_r_link1"/>
    <origin rpy="-1.1781 0 0" xyz="0.035 -0.0246 0"/>
    <axis xyz="1 0 0"/>
    <limit effort="100.0" lower="-0.85" upper="1.18" velocity="10.0"/>
  </joint>
  <!-- scissors -->
  <link name="arm_r_link2">
    <collision>
      <origin rpy="0 0 0" xyz="0 0 0"/>
      <geometry>
        <mesh filename="package://ginko_description/meshes/stl/link11_r_scissor01.stl"/>
      </geometry>
    </collision>
    <visual>
      <origin rpy="0 0 0" xyz="0 0 0"/>
      <geometry>
        <mesh filename="package://ginko_description/meshes/stl/link11_r_scissor01.stl"/>
      </geometry>
    </visual>
    <inertial>
      <mass value="0.03287850"/>
      <origin rpy="0 0 0" xyz="0.08234859 0.030246866 0.00514112"/>
      <inertia ixx="0.00002277" ixy="0.00000014" ixz="-0.00000058" iyy="0.00008197" iyz="0.00000001" izz="0.00010105"/>
    </inertial>
  </link>
  <joint name="arm_r_joint2" type="revolute">
    <parent link="arm_r_link1"/>
    <child link="arm_r_link2"/>
    <origin rpy="0 0.7854 0" xyz="0.0092 -0.0547 -0.11295"/>
    <axis xyz="0 -1 0"/>
    <limit effort="100.0" lower="-2.36" upper="2.36" velocity="10.0"/>
  </joint>
  <link name="arm_r_link3">
    <collision>
      <origin rpy="0 0 0" xyz="0 0 0"/>
      <geometry>
        <mesh filename="package://ginko_description/meshes/stl/link12_r_scissor02.stl"/>
      </geometry>
    </collision>
    <visual>
      <origin rpy="0 0 0" xyz="0 0 0"/>
      <geometry>
        <mesh filename="package://ginko_description/meshes/stl/link12_r_scissor02.stl"/>
      </geometry>
    </visual>
    <inertial>
      <mass value="0.02936110"/>
      <origin rpy="0 0 0" xyz="0.07807033 -0.02515230 -0.00665437"/>
      <inertia ixx="0.00001452" ixy="-0.00000023" ixz="-0.00000245" iyy="0.00006407" iyz="0.00000002" izz="0.00008024"/>
    </inertial>
  </link>
  <joint name="arm_r_joint3" type="revolute">
    <parent link="arm_r_link1"/>
    <child link="arm_r_link3"/>
    <origin rpy="0 0.7854 0" xyz="0.0092 0.0018 -0.11295"/>
    <axis xyz="0 -1 0"/>
    <limit effort="100.0" lower="-2.36" upper="2.36" velocity="10.0"/>
  </joint>
  <!-- LiDAR -->
  <link name="arm_r_urg_link">
    <collision>
      <origin rpy="0 0 0" xyz="0 0 0"/>
      <geometry>
        <mesh filename="package://ginko_description/meshes/stl/urg.stl"/>
      </geometry>
    </collision>
    <visual>
      <origin rpy="0 0 0" xyz="0 0 0"/>
      <geometry>
        <mesh filename="package://ginko_description/meshes/stl/urg.stl"/>
      </geometry>
    </visual>
    <inertial>
      <mass value="0.16705492"/>
      <origin rpy="0 0 0" xyz="-0.00014579 0.00000831 -0.02360505"/>
      <inertia ixx="0.00008801" ixy="0.00000000" ixz="-0.00000049" iyy="0.00008854" iyz="-0.00000004" izz="0.00006019"/>
    </inertial>
  </link>
  <!-- use zero-limited revolute joint for fixed joint (SDF) -->
  <joint name="arm_r_urg_joint" type="fixed">
    <parent link="arm_r_link1"/>
    <child link="arm_r_urg_link"/>
    <origin rpy="0 1.57 1.57" xyz="-0.0456 0.01715 -0.06795"/>
    <axis xyz="0 0 1"/>
    <limit effort="0.0" lower="0.0" upper="0.0" velocity="0.0"/>
  </joint>
  <!-- shoulder pitch. -->
  <gazebo reference="arm_r_link0">
    <kp>10000.0</kp>
    <kd>0.0</kd>
    <mu1>1.0</mu1>
    <maxVel>1.0</maxVel>
    <minDepth>0.0001</minDepth>
    <maxContacts>5</maxContacts>
    <selfCollide>false</selfCollide>
    <!-- <dampingFactor>0.01</dampingFactor> -->
  </gazebo>
  <!-- shoulder roll -->
  <gazebo reference="arm_r_link1">
    <kp>10000.0</kp>
    <kd>0.0</kd>
    <mu1>1.0</mu1>
    <maxVel>1.0</maxVel>
    <minDepth>0.0001</minDepth>
    <maxContacts>5</maxContacts>
    <selfCollide>false</selfCollide>
    <!-- <dampingFactor>0.01</dampingFactor> -->
  </gazebo>
  <!-- scissors -->
  <gazebo reference="arm_r_link2">
    <kp>10000.0</kp>
    <kd>0.0</kd>
    <mu1>1.0</mu1>
    <maxVel>1.0</maxVel>
    <minDepth>0.0001</minDepth>
    <maxContacts>5</maxContacts>
    <selfCollide>false</selfCollide>
    <!-- <dampingFactor>0.01</dampingFactor> -->
  </gazebo>
  <gazebo reference="arm_r_link3">
    <kp>10000.0</kp>
    <kd>0.0</kd>
    <mu1>1.0</mu1>
    <maxVel>1.0</maxVel>
    <minDepth>0.0001</minDepth>
    <maxContacts>5</maxContacts>
    <selfCollide>false</selfCollide>
    <!-- <dampingFactor>0.01</dampingFactor> -->
  </gazebo>
  <transmission name="arm_r_tran0">
    <type>transmission_interface/SimpleTransmission</type>
    <joint name="arm_r_joint0">
      <hardwareInterface>hardware_interface/EffortJointInterface</hardwareInterface>
    </joint>
    <actuator name="arm_r_motor0">
      <hardwareInterface>hardware_interface/EffortJointInterface</hardwareInterface>
      <mechanicalReduction>1</mechanicalReduction>
    </actuator>
  </transmission>
  <transmission name="arm_r_tran1">
    <type>transmission_interface/SimpleTransmission</type>
    <joint name="arm_r_joint1">
      <hardwareInterface>hardware_interface/EffortJointInterface</hardwareInterface>
    </joint>
    <actuator name="arm_r_motor1">
      <hardwareInterface>hardware_interface/EffortJointInterface</hardwareInterface>
      <mechanicalReduction>1</mechanicalReduction>
    </actuator>
  </transmission>
  <transmission name="arm_r_tran2">
    <type>transmission_interface/SimpleTransmission</type>
    <joint name="arm_r_joint2">
      <hardwareInterface>hardware_interface/EffortJointInterface</hardwareInterface>
    </joint>
    <actuator name="arm_r_motor2">
      <hardwareInterface>hardware_interface/EffortJointInterface</hardwareInterface>
      <mechanicalReduction>1</mechanicalReduction>
    </actuator>
  </transmission>
  <transmission name="arm_r_tran3">
    <type>transmission_interface/SimpleTransmission</type>
    <joint name="arm_r_joint3">
      <hardwareInterface>hardware_interface/EffortJointInterface</hardwareInterface>
    </joint>
    <actuator name="arm_r_motor3">
      <hardwareInterface>hardware_interface/EffortJointInterface</hardwareInterface>
      <mechanicalReduction>1</mechanicalReduction>
    </actuator>
  </transmission>
  <!-- Femoral -->
  <link name="leg_l_link0">
    <collision>
      <origin rpy="0 0 0" xyz="0 0 0"/>
      <geometry>
        <mesh filename="package://ginko_description/meshes/stl/link02_l_femoral.stl"/>
      </geometry>
    </collision>
    <visual>
      <origin rpy="0 0 0" xyz="0 0 0"/>
      <geometry>
        <mesh filename="package://ginko_description/meshes/stl/link02_l_femoral.stl"/>
      </geometry>
    </visual>
    <inertial>
      <mass value="0.03433352"/>
      <origin rpy="0 0 0" xyz="0.02930795 0.03723759 -0.02605386"/>
      <inertia ixx="0.00002443" ixy="-0.00000021" ixz="-0.00000021" iyy="0.00002287" iyz="-0.00000391" izz="0.00002983"/>
    </inertial>
  </link>
  <joint name="leg_l_joint0" type="revolute">
    <parent link="body_link1"/>
    <child link="leg_l_link0"/>
    <origin rpy="0 0 0" xyz="-0.0404 0.0 -0.0409"/>
    <axis xyz="-1 0 0"/>
    <limit effort="100.0" lower="-0.8" upper="1.1781" velocity="10.0"/>
  </joint>
  <!-- parallel link (upper-1st) -->
  <link name="leg_l_link1">
    <collision>
      <origin rpy="0 0 0" xyz="0 0 0"/>
      <geometry>
        <mesh filename="package://ginko_description/meshes/stl/link03_l_leg01.stl"/>
      </geometry>
    </collision>
    <visual>
      <origin rpy="0 0 0" xyz="0 0 0"/>
      <geometry>
        <mesh filename="package://ginko_description/meshes/stl/link03_l_leg01.stl"/>
      </geometry>
    </visual>
    <inertial>
      <mass value="0.18525692"/>
      <origin rpy="0 0 0" xyz="0.05000000 0.03285059 0.00068146"/>
      <inertia ixx="0.00041331" ixy="-0.00003605" ixz="-0.00000000" iyy="0.00027917" iyz="-0.00000184" izz="0.00066510"/>
    </inertial>
  </link>
  <joint name="leg_l_joint1" type="revolute">
    <parent link="leg_l_link0"/>
    <child link="leg_l_link1"/>
    <origin rpy="0 0.7854 0" xyz="0.0433 0.0175 -0.0481"/>
    <axis xyz="0 -1 0"/>
    <limit effort="100.0" lower="-1.3" upper="0.7854" velocity="10.0"/>
  </joint>
  <!-- parallel link (upper-2nd) -->
  <link name="leg_l_link2">
    <collision>
      <origin rpy="0 0 0" xyz="0 0 0"/>
      <geometry>
        <mesh filename="package://ginko_description/meshes/stl/link04_l_leg02.stl"/>
      </geometry>
    </collision>
    <visual>
      <origin rpy="0 0 0" xyz="0 0 0"/>
      <geometry>
        <mesh filename="package://ginko_description/meshes/stl/link04_l_leg02.stl"/>
      </geometry>
    </visual>
    <inertial>
      <mass value="0.01646643"/>
      <origin rpy="0 0 0" xyz="0.05000000 0.02495100 -0.00491150"/>
      <inertia ixx="0.00000640" ixy="0.00000000" ixz="0.00000000" iyy="0.00001642" iyz="0.00000000" izz="0.00002264"/>
    </inertial>
  </link>
  <joint name="leg_l_joint2" type="revolute">
    <parent link="leg_l_link0"/>
    <child link="leg_l_link2"/>
    <origin rpy="0 0.7854 0" xyz="0.022 0.0175 -0.06015"/>
    <axis xyz="0 -1 0"/>
    <limit effort="100.0" lower="-3.141593" upper="3.141593" velocity="10.0"/>
    <mimic joint="leg_l_joint1" multiplier="1" offset="0"/>
  </joint>
  <!-- knee -->
  <link name="leg_l_link3">
    <collision>
      <origin rpy="0 0 0" xyz="0 0 0"/>
      <geometry>
        <mesh filename="package://ginko_description/meshes/stl/link05_l_knee.stl"/>
      </geometry>
    </collision>
    <visual>
      <origin rpy="0 0 0" xyz="0 0 0"/>
      <geometry>
        <mesh filename="package://ginko_description/meshes/stl/link05_l_knee.stl"/>
      </geometry>
    </visual>
    <inertial>
      <mass value="0.01781176"/>
      <origin rpy="0 0 0" xyz="0.00393357 0.02364163 -0.01930000"/>
      <inertia ixx="0.00001301" ixy="0.00000008" ixz="0.00000000" iyy="0.00000700" iyz="0.00000000" izz="0.00001388"/>
    </inertial>
  </link>
  <joint name="leg_l_joint3" type="revolute">
    <parent link="leg_l_link1"/>
    <child link="leg_l_link3"/>
    <origin rpy="0 -0.7854 0" xyz="0.1 0.0 0.0"/>
    <axis xyz="0 1 0"/>
    <limit effort="100.0" lower="-3.141593" upper="3.141593" velocity="10.0"/>
    <mimic joint="leg_l_joint1" multiplier="1" offset="0"/>
  </joint>
  <!-- parallel link (lower-1st) -->
  <link name="leg_l_link4">
    <collision>
      <origin rpy="0 0 0" xyz="0 0 0"/>
      <geometry>
        <mesh filename="package://ginko_description/meshes/stl/link03_l_leg01.stl"/>
      </geometry>
    </collision>
    <visual>
      <origin rpy="0 0 0" xyz="0 0 0"/>
      <geometry>
        <mesh filename="package://ginko_description/meshes/stl/link03_l_leg01.stl"/>
      </geometry>
    </visual>
    <inertial>
      <mass value="0.18525692"/>
      <origin rpy="0 0 0" xyz="0.05000000 0.03285059 0.00068146"/>
      <inertia ixx="0.00041331" ixy="-0.00003605" ixz="-0.00000000" iyy="0.00027917" iyz="-0.00000184" izz="0.00066510"/>
    </inertial>
  </link>
  <joint name="leg_l_joint4" type="revolute">
    <parent link="leg_l_link3"/>
    <child link="leg_l_link4"/>
    <origin rpy="0 2.3562 0" xyz="0 0 -0.0386"/>
    <axis xyz="0 -1 0"/>
    <limit effort="100.0" lower="-0.7854" upper="1.3" velocity="10.0"/>
  </joint>
  <!-- parallel link (lower-2nd) -->
  <link name="leg_l_link5">
    <collision>
      <origin rpy="0 0 0" xyz="0 0 0"/>
      <geometry>
        <mesh filename="package://ginko_description/meshes/stl/link04_l_leg02.stl"/>
      </geometry>
    </collision>
    <visual>
      <origin rpy="0 0 0" xyz="0 0 0"/>
      <geometry>
        <mesh filename="package://ginko_description/meshes/stl/link04_l_leg02.stl"/>
      </geometry>
    </visual>
    <inertial>
      <mass value="0.01646643"/>
      <origin rpy="0 0 0" xyz="0.05000000 0.02495100 -0.00491150"/>
      <inertia ixx="0.00000640" ixy="0.00000000" ixz="0.00000000" iyy="0.00001642" iyz="0.00000000" izz="0.00002264"/>
    </inertial>
  </link>
  <joint name="leg_l_joint5" type="revolute">
    <parent link="leg_l_link3"/>
    <child link="leg_l_link5"/>
    <origin rpy="0 2.3562 0" xyz="-0.0213 0 -0.02655"/>
    <axis xyz="0 -1 0"/>
    <limit effort="100.0" lower="-3.141593" upper="3.141593" velocity="10.0"/>
    <mimic joint="leg_l_joint4" multiplier="1" offset="0"/>
  </joint>
  <!-- toe -->
  <link name="leg_l_link6">
    <collision>
      <origin rpy="0 0 0" xyz="0 0 0"/>
      <geometry>
        <mesh filename="package://ginko_description/meshes/stl/link06_l_toe01.stl"/>
      </geometry>
    </collision>
    <visual>
      <origin rpy="0 0 0" xyz="0 0 0"/>
      <geometry>
        <mesh filename="package://ginko_description/meshes/stl/link06_l_toe01.stl"/>
      </geometry>
    </visual>
    <inertial>
      <mass value="0.08799204"/>
      <origin rpy="0 0 0" xyz="-0.04166125 0.02463880 -0.02586249"/>
      <inertia ixx="0.00002815" ixy="-0.00000041" ixz="0.00000980" iyy="0.00006846" iyz="-0.00000026" izz="0.00006529"/>
    </inertial>
  </link>
  <joint name="leg_l_joint6" type="revolute">
    <parent link="leg_l_link4"/>
    <child link="leg_l_link6"/>
    <origin rpy="0 -2.3562 0" xyz="0.1 0.0 0.0"/>
    <axis xyz="0 1 0"/>
    <limit effort="100.0" lower="-3.141593" upper="3.141593" velocity="10.0"/>
    <mimic joint="leg_l_joint4" multiplier="1" offset="0"/>
  </joint>
  <link name="leg_l_link7">
    <collision>
      <origin rpy="0 0 0" xyz="0 0 0"/>
      <geometry>
        <mesh filename="package://ginko_description/meshes/stl/link07_l_toe02.stl"/>
      </geometry>
    </collision>
    <visual>
      <origin rpy="0 0 0" xyz="0 0 0"/>
      <geometry>
        <mesh filename="package://ginko_description/meshes/stl/link07_l_toe02.stl"/>
      </geometry>
    </visual>
    <inertial>
      <mass value="0.10920041"/>
      <origin rpy="0 0 0" xyz="0.02658756 0.00000053 -0.01782468"/>
      <inertia ixx="0.00003853" ixy="0.00000000" ixz="-0.00000479" iyy="0.00005192" iyz="0.00000000" izz="0.00003521"/>
    </inertial>
  </link>
  <joint name="leg_l_joint7" type="revolute">
    <parent link="leg_l_link6"/>
    <child link="leg_l_link7"/>
    <origin rpy="0 0 0" xyz="-0.028 0.02475 -0.0391"/>
    <axis xyz="-1 0 0"/>
    <limit effort="100.0" lower="-1.6" upper="1.6" velocity="10.0"/>
  </joint>
  <link name="leg_l_link8">
    <collision>
      <origin rpy="0 0 0" xyz="0 0 0"/>
      <geometry>
        <mesh filename="package://ginko_description/meshes/stl/link08_l_toe03.stl"/>
      </geometry>
    </collision>
    <visual>
      <origin rpy="0 0 0" xyz="0 0 0"/>
      <geometry>
        <mesh filename="package://ginko_description/meshes/stl/link08_l_toe03.stl"/>
      </geometry>
    </visual>
    <inertial>
      <mass value="0.05363111"/>
      <origin rpy="0 0 0" xyz="0.00000000 0.00000000 -0.00269342"/>
      <inertia ixx="0.00002877" ixy="0.00000000" ixz="0.00000000" iyy="0.00007083" iyz="-0.00000000" izz="0.00009934"/>
    </inertial>
  </link>
  <joint name="leg_l_joint8" type="revolute">
    <parent link="leg_l_link7"/>
    <child link="leg_l_link8"/>
    <origin rpy="0 0 0" xyz="0.0342 0 -0.04"/>
    <axis xyz="0 0 1"/>
    <limit effort="100.0" lower="-2.6" upper="2.6" velocity="10.0"/>
  </joint>
  <!-- Link conencts from body. Femoral first. -->
  <gazebo reference="leg_l_link0">
    <kp>10000.0</kp>
    <kd>0.0</kd>
    <mu1>0.0</mu1>
    <maxVel>3.0</maxVel>
    <minDepth>0.0001</minDepth>
    <maxContacts>5</maxContacts>
    <selfCollide>false</selfCollide>
    <dampingFactor>0.01</dampingFactor>
  </gazebo>
  <!-- parallel link (upper-1st) -->
  <gazebo reference="leg_l_link1">
    <kp>1000.0</kp>
    <kd>0.0</kd>
    <mu1>0.0</mu1>
    <maxVel>3.0</maxVel>
    <minDepth>0.0001</minDepth>
    <maxContacts>5</maxContacts>
    <selfCollide>true</selfCollide>
    <dampingFactor>0.01</dampingFactor>
  </gazebo>
  <!-- parallel link (upper-2nd) -->
  <gazebo reference="leg_l_link2">
    <kp>10000.0</kp>
    <kd>0.0</kd>
    <mu1>0.0</mu1>
    <maxVel>3.0</maxVel>
    <minDepth>0.0001</minDepth>
    <maxContacts>5</maxContacts>
    <selfCollide>false</selfCollide>
    <dampingFactor>0.01</dampingFactor>
  </gazebo>
  <!-- knee -->
  <gazebo reference="leg_l_link3">
    <kp>10000.0</kp>
    <kd>0.0</kd>
    <mu1>0.3</mu1>
    <maxVel>3.0</maxVel>
    <minDepth>0.0001</minDepth>
    <maxContacts>5</maxContacts>
    <selfCollide>false</selfCollide>
    <dampingFactor>0.01</dampingFactor>
  </gazebo>
  <!-- parallel link (lower-1st) -->
  <gazebo reference="leg_l_link4">
    <kp>1000.0</kp>
    <kd>0.0</kd>
    <mu1>0.0</mu1>
    <maxVel>3.0</maxVel>
    <minDepth>0.0001</minDepth>
    <maxContacts>5</maxContacts>
    <selfCollide>true</selfCollide>
    <dampingFactor>0.01</dampingFactor>
  </gazebo>
  <!-- parallel link (lower-2nd) -->
  <gazebo reference="leg_l_link5">
    <kp>10000.0</kp>
    <kd>0.0</kd>
    <mu1>0.0</mu1>
    <maxVel>3.0</maxVel>
    <minDepth>0.0001</minDepth>
    <maxContacts>5</maxContacts>
    <selfCollide>false</selfCollide>
    <dampingFactor>0.01</dampingFactor>
  </gazebo>
  <!-- toe -->
  <gazebo reference="leg_l_link6">
    <kp>10000.0</kp>
    <kd>0.0</kd>
    <mu1>0.0</mu1>
    <maxVel>3.0</maxVel>
    <minDepth>0.0001</minDepth>
    <maxContacts>5</maxContacts>
    <selfCollide>false</selfCollide>
    <dampingFactor>0.01</dampingFactor>
  </gazebo>
  <gazebo reference="leg_l_link7">
    <kp>10000.0</kp>
    <kd>0.0</kd>
    <mu1>0.0</mu1>
    <maxVel>3.0</maxVel>
    <minDepth>0.0001</minDepth>
    <maxContacts>5</maxContacts>
    <selfCollide>false</selfCollide>
    <dampingFactor>0.01</dampingFactor>
  </gazebo>
  <gazebo reference="leg_l_link8">
    <kp>10000.0</kp>
    <kd>0.0</kd>
    <mu1>1.0</mu1>
    <maxVel>3.0</maxVel>
    <minDepth>0.0001</minDepth>
    <maxContacts>5</maxContacts>
    <selfCollide>false</selfCollide>
    <dampingFactor>0.01</dampingFactor>
  </gazebo>
  <!-- Joints. Femoral first. -->
  <transmission name="leg_l_tran0">
    <type>transmission_interface/SimpleTransmission</type>
    <joint name="leg_l_joint0">
      <hardwareInterface>hardware_interface/EffortJointInterface</hardwareInterface>
    </joint>
    <actuator name="leg_l_motor0">
      <hardwareInterface>hardware_interface/EffortJointInterface</hardwareInterface>
      <mechanicalReduction>1</mechanicalReduction>
    </actuator>
  </transmission>
  <!-- parallel link (upper-1st) -->
  <transmission name="leg_l_tran1">
    <type>transmission_interface/SimpleTransmission</type>
    <joint name="leg_l_joint1">
      <hardwareInterface>hardware_interface/EffortJointInterface</hardwareInterface>
    </joint>
    <actuator name="leg_l_motor1">
      <hardwareInterface>hardware_interface/EffortJointInterface</hardwareInterface>
      <mechanicalReduction>1</mechanicalReduction>
    </actuator>
  </transmission>
  <!-- parallel link (lower-1st) -->
  <transmission name="leg_l_tran2">
    <type>transmission_interface/SimpleTransmission</type>
    <joint name="leg_l_joint4">
      <hardwareInterface>hardware_interface/EffortJointInterface</hardwareInterface>
    </joint>
    <actuator name="leg_l_motor2">
      <hardwareInterface>hardware_interface/EffortJointInterface</hardwareInterface>
      <mechanicalReduction>1</mechanicalReduction>
    </actuator>
  </transmission>
  <!-- toe -->
  <transmission name="leg_l_tran3">
    <type>transmission_interface/SimpleTransmission</type>
    <joint name="leg_l_joint7">
      <hardwareInterface>hardware_interface/EffortJointInterface</hardwareInterface>
    </joint>
    <actuator name="leg_l_motor3">
      <hardwareInterface>hardware_interface/EffortJointInterface</hardwareInterface>
      <mechanicalReduction>1</mechanicalReduction>
    </actuator>
  </transmission>
  <transmission name="leg_l_tran4">
    <type>transmission_interface/SimpleTransmission</type>
    <joint name="leg_l_joint8">
      <hardwareInterface>hardware_interface/EffortJointInterface</hardwareInterface>
    </joint>
    <actuator name="leg_l_motor4">
      <hardwareInterface>hardware_interface/EffortJointInterface</hardwareInterface>
      <mechanicalReduction>1</mechanicalReduction>
    </actuator>
  </transmission>
  <!-- Femoral -->
  <link name="leg_r_link0">
    <collision>
      <origin rpy="0 0 0" xyz="0 0 0"/>
      <geometry>
        <mesh filename="package://ginko_description/meshes/stl/link02_r_femoral.stl"/>
      </geometry>
    </collision>
    <visual>
      <origin rpy="0 0 0" xyz="0 0 0"/>
      <geometry>
        <mesh filename="package://ginko_description/meshes/stl/link02_r_femoral.stl"/>
      </geometry>
    </visual>
    <inertial>
      <mass value="0.03431457"/>
      <origin rpy="0 0 0" xyz="-0.02905818 -0.03723481 -0.02604954"/>
      <inertia ixx="0.00002441" ixy="0.00000001" ixz="0.00000021" iyy="0.00002285" iyz="0.00000391" izz="0.00002980"/>
    </inertial>
  </link>
  <joint name="leg_r_joint0" type="revolute">
    <parent link="body_link1"/>
    <child link="leg_r_link0"/>
    <origin rpy="0 0 0" xyz="0.0205 0.0 -0.0409"/>
    <axis xyz="1 0 0"/>
    <limit effort="100.0" lower="-1.1781" upper="0.8" velocity="10.0"/>
  </joint>
  <!-- parallel link (upper-1st) -->
  <link name="leg_r_link1">
    <collision>
      <origin rpy="0 0 0" xyz="0 0 0"/>
      <geometry>
        <mesh filename="package://ginko_description/meshes/stl/link03_r_leg01.stl"/>
      </geometry>
    </collision>
    <visual>
      <origin rpy="0 0 0" xyz="0 0 0"/>
      <geometry>
        <mesh filename="package://ginko_description/meshes/stl/link03_r_leg01.stl"/>
      </geometry>
    </visual>
    <inertial>
      <mass value="0.18525690"/>
      <origin rpy="0 0 0" xyz="0.05000000 -0.01719078 0.00068146"/>
      <inertia ixx="0.00055489" ixy="-0.00004242" ixz="0.00000000" iyy="0.00027917" iyz="-0.00000175" izz="0.00081028"/>
    </inertial>
  </link>
  <joint name="leg_r_joint1" type="revolute">
    <parent link="leg_r_link0"/>
    <child link="leg_r_link1"/>
    <origin rpy="0 0.7854 0" xyz="-0.0176 -0.0175 -0.0481"/>
    <axis xyz="0 1 0"/>
    <limit effort="100.0" lower="-0.7854" upper="1.3" velocity="10.0"/>
  </joint>
  <!-- parallel link (upper-2nd) -->
  <link name="leg_r_link2">
    <collision>
      <origin rpy="0 0 0" xyz="0 0 0"/>
      <geometry>
        <mesh filename="package://ginko_description/meshes/stl/link04_r_leg02.stl"/>
      </geometry>
    </collision>
    <visual>
      <origin rpy="0 0 0" xyz="0 0 0"/>
      <geometry>
        <mesh filename="package://ginko_description/meshes/stl/link04_r_leg02.stl"/>
      </geometry>
    </visual>
    <inertial>
      <mass value="0.01646643"/>
      <origin rpy="0 0 0" xyz="0.05000000 -0.02495100 -0.00491150"/>
      <inertia ixx="0.00000640" ixy="0.00000000" ixz="0.00000000" iyy="0.00001642" iyz="0.00000000" izz="0.00002264"/>
    </inertial>
  </link>
  <joint name="leg_r_joint2" type="revolute">
    <parent link="leg_r_link0"/>
    <child link="leg_r_link2"/>
    <origin rpy="0 0.7854 0" xyz="-0.0389 -0.0175 -0.06015"/>
    <axis xyz="0 1 0"/>
    <limit effort="100.0" lower="-3.141593" upper="3.141593" velocity="10.0"/>
    <mimic joint="leg_r_joint1" multiplier="1" offset="0"/>
  </joint>
  <!-- knee -->
  <link name="leg_r_link3">
    <collision>
      <origin rpy="0 0 0" xyz="0 0 0"/>
      <geometry>
        <mesh filename="package://ginko_description/meshes/stl/link05_r_knee.stl"/>
      </geometry>
    </collision>
    <visual>
      <origin rpy="0 0 0" xyz="0 0 0"/>
      <geometry>
        <mesh filename="package://ginko_description/meshes/stl/link05_r_knee.stl"/>
      </geometry>
    </visual>
    <inertial>
      <mass value="0.01781176"/>
      <origin rpy="0 0 0" xyz="0.00393357 -0.02364163 -0.01930000"/>
      <inertia ixx="0.00001301" ixy="-0.00000008" ixz="0.00000000" iyy="0.00000700" iyz="0.00000000" izz="0.00001388"/>
    </inertial>
  </link>
  <joint name="leg_r_joint3" type="revolute">
    <parent link="leg_r_link1"/>
    <child link="leg_r_link3"/>
    <origin rpy="0 -0.7854 0" xyz="0.1 0.0 0.0"/>
    <axis xyz="0 -1 0"/>
    <limit effort="100.0" lower="-3.141593" upper="3.141593" velocity="10.0"/>
    <mimic joint="leg_r_joint1" multiplier="1" offset="0"/>
  </joint>
  <!-- parallel link (lower-1st) -->
  <link name="leg_r_link4">
    <collision>
      <origin rpy="0 0 0" xyz="0 0 0"/>
      <geometry>
        <mesh filename="package://ginko_description/meshes/stl/link03_r_leg01.stl"/>
      </geometry>
    </collision>
    <visual>
      <origin rpy="0 0 0" xyz="0 0 0"/>
      <geometry>
        <mesh filename="package://ginko_description/meshes/stl/link03_r_leg01.stl"/>
      </geometry>
    </visual>
    <inertial>
      <mass value="0.18525690"/>
      <origin rpy="0 0 0" xyz="0.05000000 -0.01719078 0.00068146"/>
      <inertia ixx="0.00055489" ixy="-0.00004242" ixz="0.00000000" iyy="0.00027917" iyz="-0.00000175" izz="0.00081028"/>
    </inertial>
  </link>
  <joint name="leg_r_joint4" type="revolute">
    <parent link="leg_r_link3"/>
    <child link="leg_r_link4"/>
    <origin rpy="0 2.3562 0" xyz="0 0 -0.0386"/>
    <axis xyz="0 1 0"/>
    <limit effort="100.0" lower="-1.3" upper="0.7854" velocity="10.0"/>
  </joint>
  <!-- parallel link (lower-2nd) -->
  <link name="leg_r_link5">
    <collision>
      <origin rpy="0 0 0" xyz="0 0 0"/>
      <geometry>
        <mesh filename="package://ginko_description/meshes/stl/link04_r_leg02.stl"/>
      </geometry>
    </collision>
    <visual>
      <origin rpy="0 0 0" xyz="0 0 0"/>
      <geometry>
        <mesh filename="package://ginko_description/meshes/stl/link04_r_leg02.stl"/>
      </geometry>
    </visual>
    <inertial>
      <mass value="0.01646643"/>
      <origin rpy="0 0 0" xyz="0.05000000 -0.02495100 -0.00491150"/>
      <inertia ixx="0.00000640" ixy="0.00000000" ixz="0.00000000" iyy="0.00001642" iyz="0.00000000" izz="0.00002264"/>
    </inertial>
  </link>
  <joint name="leg_r_joint5" type="revolute">
    <parent link="leg_r_link3"/>
    <child link="leg_r_link5"/>
    <origin rpy="0 2.3562 0" xyz="-0.0213 0 -0.02655"/>
    <axis xyz="0 1 0"/>
    <limit effort="100.0" lower="-3.141593" upper="3.141593" velocity="10.0"/>
    <mimic joint="leg_r_joint4" multiplier="1" offset="0"/>
  </joint>
  <!-- toe -->
  <link name="leg_r_link6">
    <collision>
      <origin rpy="0 0 0" xyz="0 0 0"/>
      <geometry>
        <mesh filename="package://ginko_description/meshes/stl/link06_r_toe01.stl"/>
      </geometry>
    </collision>
    <visual>
      <origin rpy="0 0 0" xyz="0 0 0"/>
      <geometry>
        <mesh filename="package://ginko_description/meshes/stl/link06_r_toe01.stl"/>
      </geometry>
    </visual>
    <inertial>
      <mass value="0.08799204"/>
      <origin rpy="0 0 0" xyz="-0.04166125 -0.02463880 -0.02586249"/>
      <inertia ixx="0.00002815" ixy="0.00000041" ixz="0.00000980" iyy="0.00006846" iyz="0.00000026" izz="0.00006529"/>
    </inertial>
  </link>
  <joint name="leg_r_joint6" type="revolute">
    <parent link="leg_r_link4"/>
    <child link="leg_r_link6"/>
    <origin rpy="0 -2.3562 0" xyz="0.1 0.0 0.0"/>
    <axis xyz="0 -1 0"/>
    <limit effort="100.0" lower="-3.141593" upper="3.141593" velocity="10.0"/>
    <mimic joint="leg_r_joint4" multiplier="1" offset="0"/>
  </joint>
  <link name="leg_r_link7">
    <collision>
      <origin rpy="0 0 0" xyz="0 0 0"/>
      <geometry>
        <mesh filename="package://ginko_description/meshes/stl/link07_r_toe02.stl"/>
      </geometry>
    </collision>
    <visual>
      <origin rpy="0 0 0" xyz="0 0 0"/>
      <geometry>
        <mesh filename="package://ginko_description/meshes/stl/link07_r_toe02.stl"/>
      </geometry>
    </visual>
    <inertial>
      <mass value="0.10920041"/>
      <origin rpy="0 0 0" xyz="0.02658756 -0.00000053 -0.01782468"/>
      <inertia ixx="0.00003853" ixy="0.00000000" ixz="-0.00000479" iyy="0.00005192" iyz="0.00000000" izz="0.00003521"/>
    </inertial>
  </link>
  <joint name="leg_r_joint7" type="revolute">
    <parent link="leg_r_link6"/>
    <child link="leg_r_link7"/>
    <origin rpy="0 0 0" xyz="-0.028 -0.02475 -0.0391"/>
    <axis xyz="-1 0 0"/>
    <limit effort="100.0" lower="-1.6" upper="1.6" velocity="10.0"/>
  </joint>
  <link name="leg_r_link8">
    <collision>
      <origin rpy="0 0 0" xyz="0 0 0"/>
      <geometry>
        <mesh filename="package://ginko_description/meshes/stl/link08_r_toe03.stl"/>
      </geometry>
    </collision>
    <visual>
      <origin rpy="0 0 0" xyz="0 0 0"/>
      <geometry>
        <mesh filename="package://ginko_description/meshes/stl/link08_r_toe03.stl"/>
      </geometry>
    </visual>
    <inertial>
      <mass value="0.05363111"/>
      <origin rpy="0 0 0" xyz="0.00000000 0.00000000 -0.00269342"/>
      <inertia ixx="0.00002877" ixy="0.00000000" ixz="0.00000000" iyy="0.00007083" iyz="-0.00000000" izz="0.00009934"/>
    </inertial>
  </link>
  <joint name="leg_r_joint8" type="revolute">
    <parent link="leg_r_link7"/>
    <child link="leg_r_link8"/>
    <origin rpy="0 0 0" xyz="0.0342 0 -0.04"/>
    <axis xyz="0 0 1"/>
    <limit effort="100.0" lower="-2.6" upper="2.6" velocity="10.0"/>
  </joint>
  <!-- Link conencts from body. Femoral first. -->
  <gazebo reference="leg_r_link0">
    <kp>10000.0</kp>
    <kd>0.0</kd>
    <mu1>0.0</mu1>
    <maxVel>3.0</maxVel>
    <minDepth>0.0001</minDepth>
    <maxContacts>5</maxContacts>
    <selfCollide>false</selfCollide>
    <dampingFactor>0.01</dampingFactor>
  </gazebo>
  <!-- parallel link (upper-1st) -->
  <gazebo reference="leg_r_link1">
    <kp>1000.0</kp>
    <kd>0.0</kd>
    <mu1>0.0</mu1>
    <maxVel>3.0</maxVel>
    <minDepth>0.0001</minDepth>
    <maxContacts>5</maxContacts>
    <selfCollide>true</selfCollide>
    <dampingFactor>0.01</dampingFactor>
  </gazebo>
  <!-- parallel link (upper-2nd) -->
  <gazebo reference="leg_r_link2">
    <kp>10000.0</kp>
    <kd>0.0</kd>
    <mu1>0.0</mu1>
    <maxVel>3.0</maxVel>
    <minDepth>0.0001</minDepth>
    <maxContacts>5</maxContacts>
    <selfCollide>false</selfCollide>
    <dampingFactor>0.01</dampingFactor>
  </gazebo>
  <!-- knee -->
  <gazebo reference="leg_r_link3">
    <kp>10000.0</kp>
    <kd>0.0</kd>
    <mu1>0.3</mu1>
    <maxVel>3.0</maxVel>
    <minDepth>0.0001</minDepth>
    <maxContacts>5</maxContacts>
    <selfCollide>false</selfCollide>
    <dampingFactor>0.01</dampingFactor>
  </gazebo>
  <!-- parallel link (lower-1st) -->
  <gazebo reference="leg_r_link4">
    <kp>1000.0</kp>
    <kd>0.0</kd>
    <mu1>0.0</mu1>
    <maxVel>3.0</maxVel>
    <minDepth>0.0001</minDepth>
    <maxContacts>5</maxContacts>
    <selfCollide>true</selfCollide>
    <dampingFactor>0.01</dampingFactor>
  </gazebo>
  <!-- parallel link (lower-2nd) -->
  <gazebo reference="leg_r_link5">
    <kp>10000.0</kp>
    <kd>0.0</kd>
    <mu1>0.0</mu1>
    <maxVel>3.0</maxVel>
    <minDepth>0.0001</minDepth>
    <maxContacts>5</maxContacts>
    <selfCollide>false</selfCollide>
    <dampingFactor>0.01</dampingFactor>
  </gazebo>
  <!-- toe -->
  <gazebo reference="leg_r_link6">
    <kp>10000.0</kp>
    <kd>0.0</kd>
    <mu1>0.0</mu1>
    <maxVel>3.0</maxVel>
    <minDepth>0.0001</minDepth>
    <maxContacts>5</maxContacts>
    <selfCollide>false</selfCollide>
    <dampingFactor>0.01</dampingFactor>
  </gazebo>
  <gazebo reference="leg_r_link7">
    <kp>10000.0</kp>
    <kd>0.0</kd>
    <mu1>0.0</mu1>
    <maxVel>3.0</maxVel>
    <minDepth>0.0001</minDepth>
    <maxContacts>5</maxContacts>
    <selfCollide>false</selfCollide>
    <dampingFactor>0.01</dampingFactor>
  </gazebo>
  <gazebo reference="leg_r_link8">
    <kp>10000.0</kp>
    <kd>0.0</kd>
    <mu1>1.0</mu1>
    <maxVel>3.0</maxVel>
    <minDepth>0.0001</minDepth>
    <maxContacts>5</maxContacts>
    <selfCollide>false</selfCollide>
    <dampingFactor>0.01</dampingFactor>
  </gazebo>
  <!-- Joints. Femoral first. -->
  <transmission name="leg_r_tran0">
    <type>transmission_interface/SimpleTransmission</type>
    <joint name="leg_r_joint0">
      <hardwareInterface>hardware_interface/EffortJointInterface</hardwareInterface>
    </joint>
    <actuator name="leg_r_motor0">
      <hardwareInterface>hardware_interface/EffortJointInterface</hardwareInterface>
      <mechanicalReduction>1</mechanicalReduction>
    </actuator>
  </transmission>
  <!-- parallel link (upper-1st) -->
  <transmission name="leg_r_tran1">
    <type>transmission_interface/SimpleTransmission</type>
    <joint name="leg_r_joint1">
      <hardwareInterface>hardware_interface/EffortJointInterface</hardwareInterface>
    </joint>
    <actuator name="leg_r_motor1">
      <hardwareInterface>hardware_interface/EffortJointInterface</hardwareInterface>
      <mechanicalReduction>1</mechanicalReduction>
    </actuator>
  </transmission>
  <!-- parallel link (lower-1st) -->
  <transmission name="leg_r_tran2">
    <type>transmission_interface/SimpleTransmission</type>
    <joint name="leg_r_joint4">
      <hardwareInterface>hardware_interface/EffortJointInterface</hardwareInterface>
    </joint>
    <actuator name="leg_r_motor2">
      <hardwareInterface>hardware_interface/EffortJointInterface</hardwareInterface>
      <mechanicalReduction>1</mechanicalReduction>
    </actuator>
  </transmission>
  <!-- toe -->
  <transmission name="leg_r_tran3">
    <type>transmission_interface/SimpleTransmission</type>
    <joint name="leg_r_joint7">
      <hardwareInterface>hardware_interface/EffortJointInterface</hardwareInterface>
    </joint>
    <actuator name="leg_r_motor3">
      <hardwareInterface>hardware_interface/EffortJointInterface</hardwareInterface>
      <mechanicalReduction>1</mechanicalReduction>
    </actuator>
  </transmission>
  <transmission name="leg_r_tran4">
    <type>transmission_interface/SimpleTransmission</type>
    <joint name="leg_r_joint8">
      <hardwareInterface>hardware_interface/EffortJointInterface</hardwareInterface>
    </joint>
    <actuator name="leg_r_motor4">
      <hardwareInterface>hardware_interface/EffortJointInterface</hardwareInterface>
      <mechanicalReduction>1</mechanicalReduction>
    </actuator>
  </transmission>
</robot>
