<?xml version="1.0" ?>
<robot name="ginko">

  <joint name="ginko__arm_l_joint0" type="revolute">
    <parent link="ginko__body_link0"/>
    <child link="ginko__arm_l_link0"/>
    <origin rpy="0      0.3927  0" xyz="0       0.10683  0.05115"/>
    <axis xyz="0 -1  0"/>
    <limit effort="1000.0" lower="-2.6" upper="2.6" velocity="0.5"/>
  </joint>
  <joint name="ginko__arm_l_joint1" type="revolute">
    <parent link="ginko__arm_l_link0"/>
    <child link="ginko__arm_l_link1"/>
    <origin rpy="1.17809  0       0" xyz="0.035   0.0246  0"/>
    <axis xyz="1  0  0"/>
    <limit effort="1000.0" lower="-0.85" upper="1.18" velocity="0.5"/>
  </joint>
  <joint name="ginko__arm_l_joint2" type="revolute">
    <parent link="ginko__arm_l_link1"/>
    <child link="ginko__arm_l_link2"/>
    <origin rpy="0      0.7854  0" xyz="0.0092   0.0547  -0.11295"/>
    <axis xyz="0  1  0"/>
    <limit effort="1000.0" lower="-2.36" upper="2.36" velocity="0.5"/>
  </joint>
  <joint name="ginko__arm_l_joint3" type="revolute">
    <parent link="ginko__arm_l_link1"/>
    <child link="ginko__arm_l_link3"/>
    <origin rpy="0      0.7854  0" xyz="0.0092  -0.0018  -0.11295"/>
    <axis xyz="0  1  0"/>
    <limit effort="1000.0" lower="-2.36" upper="2.36" velocity="0.5"/>
  </joint>
  <joint name="ginko__arm_l_urg_joint" type="fixed">
    <parent link="ginko__arm_l_link1"/>
    <child link="ginko__arm_l_urg_link"/>
    <origin rpy="-0.00238  1.57    -1.57238" xyz="-0.0456  -0.01714 -0.06795"/>
    <axis xyz="0  0  1"/>
    <limit effort="0.0" lower="0.0" upper="0.0" velocity="0.0"/>
  </joint>
  <joint name="ginko__arm_r_joint0" type="revolute">
    <parent link="ginko__body_link0"/>
    <child link="ginko__arm_r_link0"/>
    <origin rpy="0      0.3927  0" xyz="0      -0.10683  0.05115"/>
    <axis xyz="0  1  0"/>
    <limit effort="1000.0" lower="-2.6" upper="2.6" velocity="0.5"/>
  </joint>
  <joint name="ginko__arm_r_joint1" type="revolute">
    <parent link="ginko__arm_r_link0"/>
    <child link="ginko__arm_r_link1"/>
    <origin rpy="-1.17809  0       0" xyz="0.035  -0.0246  0"/>
    <axis xyz="1  0  0"/>
    <limit effort="1000.0" lower="-0.85" upper="1.18" velocity="0.5"/>
  </joint>
  <joint name="ginko__arm_r_joint2" type="revolute">
    <parent link="ginko__arm_r_link1"/>
    <child link="ginko__arm_r_link2"/>
    <origin rpy="0      0.7854  0" xyz="0.0092  -0.0547  -0.11295"/>
    <axis xyz="0 -1  0"/>
    <limit effort="1000.0" lower="-2.36" upper="2.36" velocity="0.5"/>
  </joint>
  <joint name="ginko__arm_r_joint3" type="revolute">
    <parent link="ginko__arm_r_link1"/>
    <child link="ginko__arm_r_link3"/>
    <origin rpy="0      0.7854  0" xyz="0.0092   0.0018  -0.11295"/>
    <axis xyz="0 -1  0"/>
    <limit effort="1000.0" lower="-2.36" upper="2.36" velocity="0.5"/>
  </joint>
  <joint name="ginko__arm_r_urg_joint" type="fixed">
    <parent link="ginko__arm_r_link1"/>
    <child link="ginko__arm_r_urg_link"/>
    <origin rpy="0.00238  1.57     1.57238" xyz="-0.0456   0.01714 -0.06795"/>
    <axis xyz="0  0  1"/>
    <limit effort="0.0" lower="0.0" upper="0.0" velocity="0.0"/>
  </joint>
  <joint name="ginko__body_joint1" type="revolute">
    <parent link="ginko__body_link0"/>
    <child link="ginko__body_link1"/>
    <origin rpy="0  0  0" xyz="0  0  0"/>
    <axis xyz="0  0  1"/>
    <limit effort="1000.0" lower="-2.6" upper="2.6" velocity="0.5"/>
  </joint>
  <joint name="ginko__leg_l_joint0" type="revolute">
    <parent link="ginko__body_link1"/>
    <child link="ginko__leg_l_link0"/>
    <origin rpy="0  0  0" xyz="-0.0404  0     -0.0409"/>
    <axis xyz="-1  0  0"/>
    <limit effort="1000.0" lower="-0.8" upper="1.1781" velocity="0.5"/>
  </joint>
  <joint name="ginko__leg_l_joint1" type="revolute">
    <parent link="ginko__leg_l_link0"/>
    <child link="ginko__leg_l_link1"/>
    <origin rpy="0      0.7854  0" xyz="0.0433  0.0175 -0.0481"/>
    <axis xyz="0 -1  0"/>
    <limit effort="1000.0" lower="-1.3" upper="0.7854" velocity="0.5"/>
  </joint>
  <joint name="ginko__leg_l_joint3" type="revolute">
    <parent link="ginko__leg_l_link1"/>
    <child link="ginko__leg_l_link3"/>
    <origin rpy="0     -0.7854  0" xyz="0.1  0   0"/>
    <axis xyz="0  1  0"/>
    <limit effort="1000.0" lower="-3.14159" upper="3.14159" velocity="0.5"/>
  </joint>
  <joint name="ginko__leg_l_joint4" type="revolute">
    <parent link="ginko__leg_l_link3"/>
    <child link="ginko__leg_l_link4"/>
    <origin rpy="3.14159  0.78539  3.14159" xyz="0      0     -0.0386"/>
    <axis xyz="0 -1  0"/>
    <limit effort="1000.0" lower="-0.7854" upper="1.3" velocity="0.5"/>
  </joint>
  <joint name="ginko__leg_l_joint6" type="revolute">
    <parent link="ginko__leg_l_link4"/>
    <child link="ginko__leg_l_link6"/>
    <origin rpy="3.14159 -0.78539  3.14159" xyz="0.1  0   0"/>
    <axis xyz="0  1  0"/>
    <limit effort="1000.0" lower="-3.14159" upper="3.14159" velocity="0.5"/>
  </joint>
  <joint name="ginko__leg_l_joint7" type="revolute">
    <parent link="ginko__leg_l_link6"/>
    <child link="ginko__leg_l_link7"/>
    <origin rpy="0  0  0" xyz="-0.028    0.02475 -0.0391"/>
    <axis xyz="-1  0  0"/>
    <limit effort="1000.0" lower="-1.6" upper="1.6" velocity="0.5"/>
  </joint>
  <joint name="ginko__leg_l_joint8" type="revolute">
    <parent link="ginko__leg_l_link7"/>
    <child link="ginko__leg_l_link8"/>
    <origin rpy="0  0  0" xyz="0.0342  0     -0.04"/>
    <axis xyz="0  0  1"/>
    <limit effort="1000.0" lower="-2.6" upper="2.6" velocity="0.5"/>
  </joint>
  <joint name="ginko__leg_l_joint5" type="revolute">
    <parent link="ginko__leg_l_link3"/>
    <child link="ginko__leg_l_link5"/>
    <origin rpy="3.14159  0.78539  3.14159" xyz="-0.0213   0      -0.02655"/>
    <axis xyz="0 -1  0"/>
    <limit effort="1000.0" lower="-3.14159" upper="3.14159" velocity="0.5"/>
  </joint>
  <joint name="ginko__leg_l_joint2" type="revolute">
    <parent link="ginko__leg_l_link0"/>
    <child link="ginko__leg_l_link2"/>
    <origin rpy="0      0.7854  0" xyz="0.022    0.0175  -0.06015"/>
    <axis xyz="0 -1  0"/>
    <limit effort="1000.0" lower="-3.14159" upper="3.14159" velocity="0.5"/>
  </joint>
  <joint name="ginko__leg_r_joint0" type="revolute">
    <parent link="ginko__body_link1"/>
    <child link="ginko__leg_r_link0"/>
    <origin rpy="0  0  0" xyz="0.0205  0     -0.0409"/>
    <axis xyz="1  0  0"/>
    <limit effort="1000.0" lower="-1.1781" upper="0.8" velocity="0.5"/>
  </joint>
  <joint name="ginko__leg_r_joint1" type="revolute">
    <parent link="ginko__leg_r_link0"/>
    <child link="ginko__leg_r_link1"/>
    <origin rpy="0      0.7854  0" xyz="-0.0176 -0.0175 -0.0481"/>
    <axis xyz="0  1  0"/>
    <limit effort="1000.0" lower="-0.7854" upper="1.3" velocity="0.5"/>
  </joint>
  <joint name="ginko__leg_r_joint3" type="revolute">
    <parent link="ginko__leg_r_link1"/>
    <child link="ginko__leg_r_link3"/>
    <origin rpy="0     -0.7854  0" xyz="0.1  0   0"/>
    <axis xyz="0 -1  0"/>
    <limit effort="1000.0" lower="-3.14159" upper="3.14159" velocity="0.5"/>
  </joint>
  <joint name="ginko__leg_r_joint4" type="revolute">
    <parent link="ginko__leg_r_link3"/>
    <child link="ginko__leg_r_link4"/>
    <origin rpy="3.14159  0.78539  3.14159" xyz="0      0     -0.0386"/>
    <axis xyz="0  1  0"/>
    <limit effort="1000.0" lower="-1.3" upper="0.7854" velocity="0.5"/>
  </joint>
  <joint name="ginko__leg_r_joint6" type="revolute">
    <parent link="ginko__leg_r_link4"/>
    <child link="ginko__leg_r_link6"/>
    <origin rpy="3.14159 -0.78539  3.14159" xyz="0.1  0   0"/>
    <axis xyz="0 -1  0"/>
    <limit effort="1000.0" lower="-3.14159" upper="3.14159" velocity="0.5"/>
  </joint>
  <joint name="ginko__leg_r_joint7" type="revolute">
    <parent link="ginko__leg_r_link6"/>
    <child link="ginko__leg_r_link7"/>
    <origin rpy="0  0  0" xyz="-0.028   -0.02475 -0.0391"/>
    <axis xyz="-1  0  0"/>
    <limit effort="1000.0" lower="-1.6" upper="1.6" velocity="0.5"/>
  </joint>
  <joint name="ginko__leg_r_joint8" type="revolute">
    <parent link="ginko__leg_r_link7"/>
    <child link="ginko__leg_r_link8"/>
    <origin rpy="0  0  0" xyz="0.0342  0     -0.04"/>
    <axis xyz="0  0  1"/>
    <limit effort="1000.0" lower="-2.6" upper="2.6" velocity="0.5"/>
  </joint>
  <joint name="ginko__leg_r_joint5" type="revolute">
    <parent link="ginko__leg_r_link3"/>
    <child link="ginko__leg_r_link5"/>
    <origin rpy="3.14159  0.78539  3.14159" xyz="-0.0213   0      -0.02655"/>
    <axis xyz="0  1  0"/>
    <limit effort="1000.0" lower="-3.14159" upper="3.14159" velocity="0.5"/>
  </joint>
  <joint name="ginko__leg_r_joint2" type="revolute">
    <parent link="ginko__leg_r_link0"/>
    <child link="ginko__leg_r_link2"/>
    <origin rpy="0      0.7854  0" xyz="-0.03889 -0.0175  -0.06015"/>
    <axis xyz="0  1  0"/>
    <limit effort="1000.0" lower="-3.14159" upper="3.14159" velocity="0.5"/>
  </joint>
  <link name="ginko__body_link0">
    <inertial>
      <mass value="1.41503"/>
      <origin rpy="0  0  0" xyz="8.00000000e-05   0.00000000e+00   3.81900000e-02"/>
      <inertia ixx="0.00248548" ixy="-7.4e-07" ixz="3.761e-06" iyy="0.00121388" iyz="-4.2e-07" izz="0.00287756"/>
    </inertial>
    <collision name="ginko__body_link0_collision">
      <origin rpy="0  0  0" xyz="0  0  0"/>
      <geometry>
        <mesh filename="package://ginko_description/meshes/stl/link00_chest.stl" scale="1 1 1"/>
      </geometry>
    </collision>
    <visual name="ginko__body_link0_visual">
      <origin rpy="0  0  0" xyz="0  0  0"/>
      <geometry>
        <mesh filename="package://ginko_description/meshes/stl/link00_chest.stl" scale="1 1 1"/>
      </geometry>
    </visual>
  </link>
  <link name="ginko__arm_l_link0">
    <inertial>
      <mass value="0.0135601"/>
      <origin rpy="0  0  0" xyz="-0.01125  0.00529  0"/>
      <inertia ixx="2.35e-06" ixy="4e-08" ixz="0" iyy="1.67e-05" iyz="0" izz="1.606e-05"/>
    </inertial>
    <collision name="ginko__arm_l_link0_collision">
      <origin rpy="0  0  0" xyz="0  0  0"/>
      <geometry>
        <mesh filename="package://ginko_description/meshes/stl/link09_l_arm01.stl" scale="1 1 1"/>
      </geometry>
    </collision>
    <visual name="ginko__arm_l_link0_visual">
      <origin rpy="0  0  0" xyz="0  0  0"/>
      <geometry>
        <mesh filename="package://ginko_description/meshes/stl/link09_l_arm01.stl" scale="1 1 1"/>
      </geometry>
    </visual>
  </link>
  <link name="ginko__arm_l_link1">
    <inertial>
      <mass value="0.331399"/>
      <origin rpy="0  0  0" xyz="-0.02612  0.0265  -0.06333"/>
      <inertia ixx="0.00115128" ixy="0.00015366" ixz="-0.00031848" iyy="0.00113572" iyz="-0.00037104" izz="0.00064743"/>
    </inertial>
    <collision name="ginko__arm_l_link1_collision">
      <origin rpy="0  0  0" xyz="0  0  0"/>
      <geometry>
        <mesh filename="package://ginko_description/meshes/stl/link10_l_arm02.stl" scale="1 1 1"/>
      </geometry>
    </collision>
    <visual name="ginko__arm_l_link1_visual">
      <origin rpy="0  0  0" xyz="0  0  0"/>
      <geometry>
        <mesh filename="package://ginko_description/meshes/stl/link10_l_arm02.stl" scale="1 1 1"/>
      </geometry>
    </visual>
  </link>
  <link name="ginko__arm_l_link2">
    <inertial>
      <mass value="0.0328785"/>
      <origin rpy="0  0  0" xyz="0.08234 -0.03024  0.00514"/>
      <inertia ixx="2.277e-05" ixy="-1.4e-07" ixz="-5.8e-07" iyy="8.197e-05" iyz="-1e-08" izz="0.00010105"/>
    </inertial>
    <collision name="ginko__arm_l_link2_collision">
      <origin rpy="0  0  0" xyz="0  0  0"/>
      <geometry>
        <mesh filename="package://ginko_description/meshes/stl/link11_l_scissor01.stl" scale="1 1 1"/>
      </geometry>
    </collision>
    <visual name="ginko__arm_l_link2_visual">
      <origin rpy="0  0  0" xyz="0  0  0"/>
      <geometry>
        <mesh filename="package://ginko_description/meshes/stl/link11_l_scissor01.stl" scale="1 1 1"/>
      </geometry>
    </visual>
  </link>
  <link name="ginko__arm_l_link3">
    <inertial>
      <mass value="0.0293611"/>
      <origin rpy="0  0  0" xyz="0.07807  0.02515 -0.00665"/>
      <inertia ixx="1.452e-05" ixy="2.3e-07" ixz="-2.45e-06" iyy="6.407e-05" iyz="-2e-08" izz="8.024e-05"/>
    </inertial>
    <collision name="ginko__arm_l_link3_collision">
      <origin rpy="0  0  0" xyz="0  0  0"/>
      <geometry>
        <mesh filename="package://ginko_description/meshes/stl/link12_l_scissor02.stl" scale="1 1 1"/>
      </geometry>
    </collision>
    <visual name="ginko__arm_l_link3_visual">
      <origin rpy="0  0  0" xyz="0  0  0"/>
      <geometry>
        <mesh filename="package://ginko_description/meshes/stl/link12_l_scissor02.stl" scale="1 1 1"/>
      </geometry>
    </visual>
  </link>
  <link name="ginko__arm_l_urg_link">
    <inertial>
      <mass value="0.167055"/>
      <origin rpy="0  0  0" xyz="-0.00014  0      -0.0236"/>
      <inertia ixx="8.801e-05" ixy="0" ixz="-4.9e-07" iyy="8.854e-05" iyz="-4e-08" izz="6.019e-05"/>
    </inertial>
    <collision name="ginko__arm_l_urg_link_collision">
      <origin rpy="0  0  0" xyz="0  0  0"/>
      <geometry>
        <mesh filename="package://ginko_description/meshes/stl/urg.stl" scale="1 1 1"/>
      </geometry>
    </collision>
    <visual name="ginko__arm_l_urg_link_visual">
      <origin rpy="0  0  0" xyz="0  0  0"/>
      <geometry>
        <mesh filename="package://ginko_description/meshes/stl/urg.stl" scale="1 1 1"/>
      </geometry>
    </visual>
  </link>
  <link name="ginko__arm_r_link0">
    <inertial>
      <mass value="0.0135601"/>
      <origin rpy="0  0  0" xyz="-0.01125 -0.00529  0"/>
      <inertia ixx="2.35e-06" ixy="-4e-08" ixz="0" iyy="1.67e-05" iyz="0" izz="1.606e-05"/>
    </inertial>
    <collision name="ginko__arm_r_link0_collision">
      <origin rpy="0  0  0" xyz="0  0  0"/>
      <geometry>
        <mesh filename="package://ginko_description/meshes/stl/link09_r_arm01.stl" scale="1 1 1"/>
      </geometry>
    </collision>
    <visual name="ginko__arm_r_link0_visual">
      <origin rpy="0  0  0" xyz="0  0  0"/>
      <geometry>
        <mesh filename="package://ginko_description/meshes/stl/link09_r_arm01.stl" scale="1 1 1"/>
      </geometry>
    </visual>
  </link>
  <link name="ginko__arm_r_link1">
    <inertial>
      <mass value="0.331399"/>
      <origin rpy="0  0  0" xyz="-0.02612 -0.0265  -0.06333"/>
      <inertia ixx="0.00115128" ixy="-0.00015366" ixz="-0.00031848" iyy="0.00113572" iyz="0.00037104" izz="0.00064743"/>
    </inertial>
    <collision name="ginko__arm_r_link1_collision">
      <origin rpy="0  0  0" xyz="0  0  0"/>
      <geometry>
        <mesh filename="package://ginko_description/meshes/stl/link10_r_arm02.stl" scale="1 1 1"/>
      </geometry>
    </collision>
    <visual name="ginko__arm_r_link1_visual">
      <origin rpy="0  0  0" xyz="0  0  0"/>
      <geometry>
        <mesh filename="package://ginko_description/meshes/stl/link10_r_arm02.stl" scale="1 1 1"/>
      </geometry>
    </visual>
  </link>
  <link name="ginko__arm_r_link2">
    <inertial>
      <mass value="0.0328785"/>
      <origin rpy="0  0  0" xyz="0.08234  0.03024  0.00514"/>
      <inertia ixx="2.277e-05" ixy="1.4e-07" ixz="-5.8e-07" iyy="8.197e-05" iyz="1e-08" izz="0.00010105"/>
    </inertial>
    <collision name="ginko__arm_r_link2_collision">
      <origin rpy="0  0  0" xyz="0  0  0"/>
      <geometry>
        <mesh filename="package://ginko_description/meshes/stl/link11_r_scissor01.stl" scale="1 1 1"/>
      </geometry>
    </collision>
    <visual name="ginko__arm_r_link2_visual">
      <origin rpy="0  0  0" xyz="0  0  0"/>
      <geometry>
        <mesh filename="package://ginko_description/meshes/stl/link11_r_scissor01.stl" scale="1 1 1"/>
      </geometry>
    </visual>
  </link>
  <link name="ginko__arm_r_link3">
    <inertial>
      <mass value="0.0293611"/>
      <origin rpy="0  0  0" xyz="0.07807 -0.02515 -0.00665"/>
      <inertia ixx="1.452e-05" ixy="-2.3e-07" ixz="-2.45e-06" iyy="6.407e-05" iyz="2e-08" izz="8.024e-05"/>
    </inertial>
    <collision name="ginko__arm_r_link3_collision">
      <origin rpy="0  0  0" xyz="0  0  0"/>
      <geometry>
        <mesh filename="package://ginko_description/meshes/stl/link12_r_scissor02.stl" scale="1 1 1"/>
      </geometry>
    </collision>
    <visual name="ginko__arm_r_link3_visual">
      <origin rpy="0  0  0" xyz="0  0  0"/>
      <geometry>
        <mesh filename="package://ginko_description/meshes/stl/link12_r_scissor02.stl" scale="1 1 1"/>
      </geometry>
    </visual>
  </link>
  <link name="ginko__arm_r_urg_link">
    <inertial>
      <mass value="0.167055"/>
      <origin rpy="0  0  0" xyz="-0.00014  0      -0.0236"/>
      <inertia ixx="8.801e-05" ixy="0" ixz="-4.9e-07" iyy="8.854e-05" iyz="-4e-08" izz="6.019e-05"/>
    </inertial>
    <collision name="ginko__arm_r_urg_link_collision">
      <origin rpy="0  0  0" xyz="0  0  0"/>
      <geometry>
        <mesh filename="package://ginko_description/meshes/stl/urg.stl" scale="1 1 1"/>
      </geometry>
    </collision>
    <visual name="ginko__arm_r_urg_link_visual">
      <origin rpy="0  0  0" xyz="0  0  0"/>
      <geometry>
        <mesh filename="package://ginko_description/meshes/stl/urg.stl" scale="1 1 1"/>
      </geometry>
    </visual>
  </link>
  <link name="ginko__body_link1">
    <inertial>
      <mass value="0.333127"/>
      <origin rpy="0  0  0" xyz="-0.01135  0      -0.0272"/>
      <inertia ixx="0.00015328" ixy="3e-08" ixz="1.078e-05" iyy="0.00073745" iyz="0" izz="0.00073107"/>
    </inertial>
    <collision name="ginko__body_link1_collision">
      <origin rpy="0  0  0" xyz="0  0  0"/>
      <geometry>
        <mesh filename="package://ginko_description/meshes/stl/link01_waist.stl" scale="1 1 1"/>
      </geometry>
    </collision>
    <visual name="ginko__body_link1_visual">
      <origin rpy="0  0  0" xyz="0  0  0"/>
      <geometry>
        <mesh filename="package://ginko_description/meshes/stl/link01_waist.stl" scale="1 1 1"/>
      </geometry>
    </visual>
  </link>
  <link name="ginko__leg_l_link0">
    <inertial>
      <mass value="0.0343335"/>
      <origin rpy="0  0  0" xyz="0.0293   0.03723 -0.02605"/>
      <inertia ixx="2.443e-05" ixy="-2.1e-07" ixz="-2.1e-07" iyy="2.287e-05" iyz="-3.91e-06" izz="2.983e-05"/>
    </inertial>
    <collision name="ginko__leg_l_link0_collision">
      <origin rpy="0  0  0" xyz="0  0  0"/>
      <geometry>
        <mesh filename="package://ginko_description/meshes/stl/link02_l_femoral.stl" scale="1 1 1"/>
      </geometry>
    </collision>
    <visual name="ginko__leg_l_link0_visual">
      <origin rpy="0  0  0" xyz="0  0  0"/>
      <geometry>
        <mesh filename="package://ginko_description/meshes/stl/link02_l_femoral.stl" scale="1 1 1"/>
      </geometry>
    </visual>
  </link>
  <link name="ginko__leg_l_link1">
    <inertial>
      <mass value="0.185257"/>
      <origin rpy="0  0  0" xyz="0.05     0.03285  0.00068"/>
      <inertia ixx="0.00041331" ixy="-3.605e-05" ixz="-0" iyy="0.00027917" iyz="-1.84e-06" izz="0.0006651"/>
    </inertial>
    <collision name="ginko__leg_l_link1_collision">
      <origin rpy="0  0  0" xyz="0  0  0"/>
      <geometry>
        <mesh filename="package://ginko_description/meshes/stl/link03_l_leg01.stl" scale="1 1 1"/>
      </geometry>
    </collision>
    <visual name="ginko__leg_l_link1_visual">
      <origin rpy="0  0  0" xyz="0  0  0"/>
      <geometry>
        <mesh filename="package://ginko_description/meshes/stl/link03_l_leg01.stl" scale="1 1 1"/>
      </geometry>
    </visual>
  </link>
  <link name="ginko__leg_l_link3">
    <inertial>
      <mass value="0.0178118"/>
      <origin rpy="0  0  0" xyz="0.00393  0.02364 -0.0193"/>
      <inertia ixx="1.301e-05" ixy="8e-08" ixz="0" iyy="7e-06" iyz="0" izz="1.388e-05"/>
    </inertial>
    <collision name="ginko__leg_l_link3_collision">
      <origin rpy="0  0  0" xyz="0  0  0"/>
      <geometry>
        <mesh filename="package://ginko_description/meshes/stl/link05_l_knee.stl" scale="1 1 1"/>
      </geometry>
    </collision>
    <visual name="ginko__leg_l_link3_visual">
      <origin rpy="0  0  0" xyz="0  0  0"/>
      <geometry>
        <mesh filename="package://ginko_description/meshes/stl/link05_l_knee.stl" scale="1 1 1"/>
      </geometry>
    </visual>
  </link>
  <link name="ginko__leg_l_link4">
    <inertial>
      <mass value="0.185257"/>
      <origin rpy="0  0  0" xyz="0.05     0.03285  0.00068"/>
      <inertia ixx="0.00041331" ixy="-3.605e-05" ixz="-0" iyy="0.00027917" iyz="-1.84e-06" izz="0.0006651"/>
    </inertial>
    <collision name="ginko__leg_l_link4_collision">
      <origin rpy="0  0  0" xyz="0  0  0"/>
      <geometry>
        <mesh filename="package://ginko_description/meshes/stl/link03_l_leg01.stl" scale="1 1 1"/>
      </geometry>
    </collision>
    <visual name="ginko__leg_l_link4_visual">
      <origin rpy="0  0  0" xyz="0  0  0"/>
      <geometry>
        <mesh filename="package://ginko_description/meshes/stl/link03_l_leg01.stl" scale="1 1 1"/>
      </geometry>
    </visual>
  </link>
  <link name="ginko__leg_l_link6">
    <inertial>
      <mass value="0.087992"/>
      <origin rpy="0  0  0" xyz="-0.04166  0.02463 -0.02586"/>
      <inertia ixx="2.815e-05" ixy="-4.1e-07" ixz="9.8e-06" iyy="6.846e-05" iyz="-2.6e-07" izz="6.529e-05"/>
    </inertial>
    <collision name="ginko__leg_l_link6_collision">
      <origin rpy="0  0  0" xyz="0  0  0"/>
      <geometry>
        <mesh filename="package://ginko_description/meshes/stl/link06_l_toe01.stl" scale="1 1 1"/>
      </geometry>
    </collision>
    <visual name="ginko__leg_l_link6_visual">
      <origin rpy="0  0  0" xyz="0  0  0"/>
      <geometry>
        <mesh filename="package://ginko_description/meshes/stl/link06_l_toe01.stl" scale="1 1 1"/>
      </geometry>
    </visual>
  </link>
  <link name="ginko__leg_l_link7">
    <inertial>
      <mass value="0.1092"/>
      <origin rpy="0  0  0" xyz="0.02658  0      -0.01782"/>
      <inertia ixx="3.853e-05" ixy="0" ixz="-4.79e-06" iyy="5.192e-05" iyz="0" izz="3.521e-05"/>
    </inertial>
    <collision name="ginko__leg_l_link7_collision">
      <origin rpy="0  0  0" xyz="0  0  0"/>
      <geometry>
        <mesh filename="package://ginko_description/meshes/stl/link07_l_toe02.stl" scale="1 1 1"/>
      </geometry>
    </collision>
    <visual name="ginko__leg_l_link7_visual">
      <origin rpy="0  0  0" xyz="0  0  0"/>
      <geometry>
        <mesh filename="package://ginko_description/meshes/stl/link07_l_toe02.stl" scale="1 1 1"/>
      </geometry>
    </visual>
  </link>
  <link name="ginko__leg_l_link8">
    <inertial>
      <mass value="0.0536311"/>
      <origin rpy="0  0  0" xyz="0       0      -0.00269"/>
      <inertia ixx="2.877e-05" ixy="0" ixz="0" iyy="7.083e-05" iyz="-0" izz="9.934e-05"/>
    </inertial>
    <collision name="ginko__leg_l_link8_collision">
      <origin rpy="0  0  0" xyz="0  0  0"/>
      <geometry>
        <mesh filename="package://ginko_description/meshes/stl/link08_l_toe03.stl" scale="1 1 1"/>
      </geometry>
    </collision>
    <visual name="ginko__leg_l_link8_visual">
      <origin rpy="0  0  0" xyz="0  0  0"/>
      <geometry>
        <mesh filename="package://ginko_description/meshes/stl/link08_l_toe03.stl" scale="1 1 1"/>
      </geometry>
    </visual>
  </link>
  <link name="ginko__leg_l_link5">
    <inertial>
      <mass value="0.0164664"/>
      <origin rpy="0  0  0" xyz="0.05     0.02495 -0.00491"/>
      <inertia ixx="6.4e-06" ixy="0" ixz="0" iyy="1.642e-05" iyz="0" izz="2.264e-05"/>
    </inertial>
    <collision name="ginko__leg_l_link5_collision">
      <origin rpy="0  0  0" xyz="0  0  0"/>
      <geometry>
        <mesh filename="package://ginko_description/meshes/stl/link04_l_leg02.stl" scale="1 1 1"/>
      </geometry>
    </collision>
    <visual name="ginko__leg_l_link5_visual">
      <origin rpy="0  0  0" xyz="0  0  0"/>
      <geometry>
        <mesh filename="package://ginko_description/meshes/stl/link04_l_leg02.stl" scale="1 1 1"/>
      </geometry>
    </visual>
  </link>
  <link name="ginko__leg_l_link2">
    <inertial>
      <mass value="0.0164664"/>
      <origin rpy="0  0  0" xyz="0.05     0.02495 -0.00491"/>
      <inertia ixx="6.4e-06" ixy="0" ixz="0" iyy="1.642e-05" iyz="0" izz="2.264e-05"/>
    </inertial>
    <collision name="ginko__leg_l_link2_collision">
      <origin rpy="0  0  0" xyz="0  0  0"/>
      <geometry>
        <mesh filename="package://ginko_description/meshes/stl/link04_l_leg02.stl" scale="1 1 1"/>
      </geometry>
    </collision>
    <visual name="ginko__leg_l_link2_visual">
      <origin rpy="0  0  0" xyz="0  0  0"/>
      <geometry>
        <mesh filename="package://ginko_description/meshes/stl/link04_l_leg02.stl" scale="1 1 1"/>
      </geometry>
    </visual>
  </link>
  <link name="ginko__leg_r_link0">
    <inertial>
      <mass value="0.0343146"/>
      <origin rpy="0  0  0" xyz="-0.02905 -0.03723 -0.02605"/>
      <inertia ixx="2.441e-05" ixy="1e-08" ixz="2.1e-07" iyy="2.285e-05" iyz="3.91e-06" izz="2.98e-05"/>
    </inertial>
    <collision name="ginko__leg_r_link0_collision">
      <origin rpy="0  0  0" xyz="0  0  0"/>
      <geometry>
        <mesh filename="package://ginko_description/meshes/stl/link02_r_femoral.stl" scale="1 1 1"/>
      </geometry>
    </collision>
    <visual name="ginko__leg_r_link0_visual">
      <origin rpy="0  0  0" xyz="0  0  0"/>
      <geometry>
        <mesh filename="package://ginko_description/meshes/stl/link02_r_femoral.stl" scale="1 1 1"/>
      </geometry>
    </visual>
  </link>
  <link name="ginko__leg_r_link1">
    <inertial>
      <mass value="0.185257"/>
      <origin rpy="0  0  0" xyz="0.05    -0.01719  0.00068"/>
      <inertia ixx="0.00055489" ixy="-4.242e-05" ixz="0" iyy="0.00027917" iyz="-1.75e-06" izz="0.00081028"/>
    </inertial>
    <collision name="ginko__leg_r_link1_collision">
      <origin rpy="0  0  0" xyz="0  0  0"/>
      <geometry>
        <mesh filename="package://ginko_description/meshes/stl/link03_r_leg01.stl" scale="1 1 1"/>
      </geometry>
    </collision>
    <visual name="ginko__leg_r_link1_visual">
      <origin rpy="0  0  0" xyz="0  0  0"/>
      <geometry>
        <mesh filename="package://ginko_description/meshes/stl/link03_r_leg01.stl" scale="1 1 1"/>
      </geometry>
    </visual>
  </link>
  <link name="ginko__leg_r_link3">
    <inertial>
      <mass value="0.0178118"/>
      <origin rpy="0  0  0" xyz="0.00393 -0.02364 -0.0193"/>
      <inertia ixx="1.301e-05" ixy="-8e-08" ixz="0" iyy="7e-06" iyz="0" izz="1.388e-05"/>
    </inertial>
    <collision name="ginko__leg_r_link3_collision">
      <origin rpy="0  0  0" xyz="0  0  0"/>
      <geometry>
        <mesh filename="package://ginko_description/meshes/stl/link05_r_knee.stl" scale="1 1 1"/>
      </geometry>
    </collision>
    <visual name="ginko__leg_r_link3_visual">
      <origin rpy="0  0  0" xyz="0  0  0"/>
      <geometry>
        <mesh filename="package://ginko_description/meshes/stl/link05_r_knee.stl" scale="1 1 1"/>
      </geometry>
    </visual>
  </link>
  <link name="ginko__leg_r_link4">
    <inertial>
      <mass value="0.185257"/>
      <origin rpy="0  0  0" xyz="0.05    -0.01719  0.00068"/>
      <inertia ixx="0.00055489" ixy="-4.242e-05" ixz="0" iyy="0.00027917" iyz="-1.75e-06" izz="0.00081028"/>
    </inertial>
    <collision name="ginko__leg_r_link4_collision">
      <origin rpy="0  0  0" xyz="0  0  0"/>
      <geometry>
        <mesh filename="package://ginko_description/meshes/stl/link03_r_leg01.stl" scale="1 1 1"/>
      </geometry>
    </collision>
    <visual name="ginko__leg_r_link4_visual">
      <origin rpy="0  0  0" xyz="0  0  0"/>
      <geometry>
        <mesh filename="package://ginko_description/meshes/stl/link03_r_leg01.stl" scale="1 1 1"/>
      </geometry>
    </visual>
  </link>
  <link name="ginko__leg_r_link6">
    <inertial>
      <mass value="0.087992"/>
      <origin rpy="0  0  0" xyz="-0.04166 -0.02463 -0.02586"/>
      <inertia ixx="2.815e-05" ixy="4.1e-07" ixz="9.8e-06" iyy="6.846e-05" iyz="2.6e-07" izz="6.529e-05"/>
    </inertial>
    <collision name="ginko__leg_r_link6_collision">
      <origin rpy="0  0  0" xyz="0  0  0"/>
      <geometry>
        <mesh filename="package://ginko_description/meshes/stl/link06_r_toe01.stl" scale="1 1 1"/>
      </geometry>
    </collision>
    <visual name="ginko__leg_r_link6_visual">
      <origin rpy="0  0  0" xyz="0  0  0"/>
      <geometry>
        <mesh filename="package://ginko_description/meshes/stl/link06_r_toe01.stl" scale="1 1 1"/>
      </geometry>
    </visual>
  </link>
  <link name="ginko__leg_r_link7">
    <inertial>
      <mass value="0.1092"/>
      <origin rpy="0  0  0" xyz="0.02658  0      -0.01782"/>
      <inertia ixx="3.853e-05" ixy="0" ixz="-4.79e-06" iyy="5.192e-05" iyz="0" izz="3.521e-05"/>
    </inertial>
    <collision name="ginko__leg_r_link7_collision">
      <origin rpy="0  0  0" xyz="0  0  0"/>
      <geometry>
        <mesh filename="package://ginko_description/meshes/stl/link07_r_toe02.stl" scale="1 1 1"/>
      </geometry>
    </collision>
    <visual name="ginko__leg_r_link7_visual">
      <origin rpy="0  0  0" xyz="0  0  0"/>
      <geometry>
        <mesh filename="package://ginko_description/meshes/stl/link07_r_toe02.stl" scale="1 1 1"/>
      </geometry>
    </visual>
  </link>
  <link name="ginko__leg_r_link8">
    <inertial>
      <mass value="0.0536311"/>
      <origin rpy="0  0  0" xyz="0       0      -0.00269"/>
      <inertia ixx="2.877e-05" ixy="0" ixz="0" iyy="7.083e-05" iyz="-0" izz="9.934e-05"/>
    </inertial>
    <collision name="ginko__leg_r_link8_collision">
      <origin rpy="0  0  0" xyz="0  0  0"/>
      <geometry>
        <mesh filename="package://ginko_description/meshes/stl/link08_r_toe03.stl" scale="1 1 1"/>
      </geometry>
    </collision>
    <visual name="ginko__leg_r_link8_visual">
      <origin rpy="0  0  0" xyz="0  0  0"/>
      <geometry>
        <mesh filename="package://ginko_description/meshes/stl/link08_r_toe03.stl" scale="1 1 1"/>
      </geometry>
    </visual>
  </link>
  <link name="ginko__leg_r_link5">
    <inertial>
      <mass value="0.0164664"/>
      <origin rpy="0  0  0" xyz="0.05    -0.02495 -0.00491"/>
      <inertia ixx="6.4e-06" ixy="0" ixz="0" iyy="1.642e-05" iyz="0" izz="2.264e-05"/>
    </inertial>
    <collision name="ginko__leg_r_link5_collision">
      <origin rpy="0  0  0" xyz="0  0  0"/>
      <geometry>
        <mesh filename="package://ginko_description/meshes/stl/link04_r_leg02.stl" scale="1 1 1"/>
      </geometry>
    </collision>
    <visual name="ginko__leg_r_link5_visual">
      <origin rpy="0  0  0" xyz="0  0  0"/>
      <geometry>
        <mesh filename="package://ginko_description/meshes/stl/link04_r_leg02.stl" scale="1 1 1"/>
      </geometry>
    </visual>
  </link>
  <link name="ginko__leg_r_link2">
    <inertial>
      <mass value="0.0164664"/>
      <origin rpy="0  0  0" xyz="0.05    -0.02495 -0.00491"/>
      <inertia ixx="6.4e-06" ixy="0" ixz="0" iyy="1.642e-05" iyz="0" izz="2.264e-05"/>
    </inertial>
    <collision name="ginko__leg_r_link2_collision">
      <origin rpy="0  0  0" xyz="0  0  0"/>
      <geometry>
        <mesh filename="package://ginko_description/meshes/stl/link04_r_leg02.stl" scale="1 1 1"/>
      </geometry>
    </collision>
    <visual name="ginko__leg_r_link2_visual">
      <origin rpy="0  0  0" xyz="0  0  0"/>
      <geometry>
        <mesh filename="package://ginko_description/meshes/stl/link04_r_leg02.stl" scale="1 1 1"/>
      </geometry>
    </visual>
  </link>
  <!-- transmissions -->
  <!-- left leg -->
  <transmission name="leg_l_tran0">
    <type>transmission_interface/SimpleTransmission</type>
    <joint name="leg_l_joint0">
      <hardwareInterface>hardware_interface/EffortJointInterface</hardwareInterface>
    </joint>
    <actuator name="leg_l_motor0">
      <hardwareInterface>hardware_interface/EffortJointInterface</hardwareInterface>
      <mechanicalReduction>1</mechanicalReduction>
    </actuator>
  </transmission>
  <transmission name="leg_l_tran1">
    <type>transmission_interface/SimpleTransmission</type>
    <joint name="leg_l_joint1">
      <hardwareInterface>hardware_interface/EffortJointInterface</hardwareInterface>
    </joint>
    <actuator name="leg_l_motor1">
      <hardwareInterface>hardware_interface/EffortJointInterface</hardwareInterface>
      <mechanicalReduction>1</mechanicalReduction>
    </actuator>
  <transmission name="leg_l_tran2">
    <type>transmission_interface/SimpleTransmission</type>
    <joint name="leg_l_joint4">
      <hardwareInterface>hardware_interface/EffortJointInterface</hardwareInterface>
    </joint>
    <actuator name="leg_l_motor2">
      <hardwareInterface>hardware_interface/EffortJointInterface</hardwareInterface>
      <mechanicalReduction>1</mechanicalReduction>
    </actuator>
  </transmission>
  <transmission name="leg_l_tran3">
    <type>transmission_interface/SimpleTransmission</type>
    <joint name="leg_l_joint7">
      <hardwareInterface>hardware_interface/EffortJointInterface</hardwareInterface>
    </joint>
    <actuator name="leg_l_motor3">
      <hardwareInterface>hardware_interface/EffortJointInterface</hardwareInterface>
      <mechanicalReduction>1</mechanicalReduction>
    </actuator>
  </transmission>

  <transmission name="leg_l_tran4">
    <type>transmission_interface/SimpleTransmission</type>
    <joint name="leg_l_joint8">
      <hardwareInterface>hardware_interface/EffortJointInterface</hardwareInterface>
    </joint>
    <actuator name="leg_l_motor4">
      <hardwareInterface>hardware_interface/EffortJointInterface</hardwareInterface>
      <mechanicalReduction>1</mechanicalReduction>
    </actuator>
  </transmission>

</robot>
