<sdf version='1.6'>
  <model name='ginko_xacro'>
    <link name='body_link0'>
      <pose frame=''>0 0 0 0 -0 0</pose>
      <inertial>
        <pose frame=''>8.3e-05 9e-06 0.038196 0 -0 0</pose>
        <mass>1.41503</mass>
        <inertia>
          <ixx>0.00248548</ixx>
          <ixy>-7.4e-07</ixy>
          <ixz>3.761e-06</ixz>
          <iyy>0.00121388</iyy>
          <iyz>-4.2e-07</iyz>
          <izz>0.00287756</izz>
        </inertia>
      </inertial>
      <collision name='body_link0_collision'>
        <pose frame=''>0 0 0 0 -0 0</pose>
        <geometry>
          <mesh>
            <scale>1 1 1</scale>
            <uri>model://ginko_description/meshes/stl/link00_chest.stl</uri>
          </mesh>
        </geometry>
        <surface>
          <contact>
            <ode>
              <kp>1e+06</kp>
              <kd>100</kd>
              <max_vel>3</max_vel>
              <min_depth>0.0001</min_depth>
            </ode>
          </contact>
          <friction>
            <ode>
              <mu>0.1</mu>
            </ode>
          </friction>
        </surface>
        <max_contacts>5</max_contacts>
      </collision>
      <visual name='body_link0_visual'>
        <pose frame=''>0 0 0 0 -0 0</pose>
        <geometry>
          <mesh>
            <scale>1 1 1</scale>
            <uri>model://ginko_description/meshes/obj/link00_chest.obj</uri>
          </mesh>
        </geometry>
        <material>
          <script>
            <uri>__default__</uri>
            <name>__default__</name>
          </script>
        </material>
      </visual>
      <gravity>1</gravity>
      <velocity_decay>
        <linear>0.001</linear>
        <angular>0.001</angular>
      </velocity_decay>
      <self_collide>0</self_collide>
    </link>
    <link name='body_link1'>
      <pose frame=''>0 0 0 0 -0 0</pose>
      <inertial>
        <pose frame=''>-0.011355 -1e-06 -0.027202 0 -0 0</pose>
        <mass>0.333127</mass>
        <inertia>
          <ixx>0.00015328</ixx>
          <ixy>3e-08</ixy>
          <ixz>1.078e-05</ixz>
          <iyy>0.00073745</iyy>
          <iyz>0</iyz>
          <izz>0.00073107</izz>
        </inertia>
      </inertial>
      <collision name='body_link1_collision'>
        <pose frame=''>0 0 0 0 -0 0</pose>
        <geometry>
          <mesh>
            <scale>1 1 1</scale>
            <uri>model://ginko_description/meshes/stl/link01_waist.stl</uri>
          </mesh>
        </geometry>
        <surface>
          <contact>
            <ode>
              <kp>1e+06</kp>
              <kd>100</kd>
              <max_vel>3</max_vel>
              <min_depth>0.0001</min_depth>
            </ode>
          </contact>
          <friction>
            <ode>
              <mu>0.1</mu>
            </ode>
          </friction>
        </surface>
        <max_contacts>5</max_contacts>
      </collision>
      <visual name='body_link1_visual'>
        <pose frame=''>0 0 0 0 -0 0</pose>
        <geometry>
          <mesh>
            <scale>1 1 1</scale>
            <uri>model://ginko_description/meshes/obj/link01_waist.obj</uri>
          </mesh>
        </geometry>
        <material>
          <script>
            <uri>__default__</uri>
            <name>__default__</name>
          </script>
        </material>
      </visual>
      <gravity>1</gravity>
      <velocity_decay>
        <linear>0.001</linear>
        <angular>0.001</angular>
      </velocity_decay>
      <self_collide>0</self_collide>
    </link>
    <joint name='body_joint1' type='revolute'>
      <child>body_link1</child>
      <parent>body_link0</parent>
      <axis>
        <xyz>0 0 1</xyz>
        <limit>
          <lower>-2.6</lower>
          <upper>2.6</upper>
          <effort>1000</effort>
          <velocity>10</velocity>
        </limit>
        <dynamics>
          <damping>0.1</damping>
          <friction>0.1</friction>
          <spring_reference>0</spring_reference>
          <spring_stiffness>0</spring_stiffness>
        </dynamics>
        <use_parent_model_frame>1</use_parent_model_frame>
      </axis>
    </joint>
    <link name='leg_r_link0'>
      <pose frame=''>0.0205 0 -0.0409 0 -0 0</pose>
      <inertial>
        <pose frame=''>-0.029058 -0.037235 -0.02605 0 -0 0</pose>
        <mass>0.0343146</mass>
        <inertia>
          <ixx>2.441e-05</ixx>
          <ixy>1e-08</ixy>
          <ixz>2.1e-07</ixz>
          <iyy>2.285e-05</iyy>
          <iyz>3.91e-06</iyz>
          <izz>2.98e-05</izz>
        </inertia>
      </inertial>
      <collision name='leg_r_link0_collision'>
        <pose frame=''>0 0 0 0 -0 0</pose>
        <geometry>
          <mesh>
            <scale>1 1 1</scale>
            <uri>model://ginko_description/meshes/stl/link02_r_femoral.stl</uri>
          </mesh>
        </geometry>
        <surface>
          <contact>
            <ode>
              <kp>1e+06</kp>
              <kd>100</kd>
              <max_vel>3</max_vel>
              <min_depth>0.0001</min_depth>
            </ode>
          </contact>
          <friction>
            <ode>
              <mu>0.1</mu>
            </ode>
          </friction>
        </surface>
        <max_contacts>5</max_contacts>
      </collision>
      <visual name='leg_r_link0_visual'>
        <pose frame=''>0 0 0 0 -0 0</pose>
        <geometry>
          <mesh>
            <scale>1 1 1</scale>
            <uri>model://ginko_description/meshes/obj/link02_r_femoral.obj</uri>
          </mesh>
        </geometry>
        <material>
          <script>
            <uri>__default__</uri>
            <name>__default__</name>
          </script>
        </material>
      </visual>
      <gravity>1</gravity>
      <velocity_decay>
        <linear>0.001</linear>
        <angular>0.001</angular>
      </velocity_decay>
      <self_collide>0</self_collide>
    </link>
    <joint name='leg_r_joint0' type='revolute'>
      <child>leg_r_link0</child>
      <parent>body_link1</parent>
      <axis>
        <xyz>1 0 0</xyz>
        <limit>
          <lower>-1</lower>
          <upper>0.8</upper>
          <effort>1000</effort>
          <velocity>10</velocity>
        </limit>
        <dynamics>
          <damping>0.1</damping>
          <friction>0.1</friction>
          <spring_reference>0</spring_reference>
          <spring_stiffness>0</spring_stiffness>
        </dynamics>
        <use_parent_model_frame>1</use_parent_model_frame>
      </axis>
    </joint>
    <link name='leg_r_link1'>
      <pose frame=''>0.0029 -0.0175 -0.089 0 0.7854 0</pose>
      <inertial>
        <pose frame=''>0.05 -0.017191 0.000681 0 -0 0</pose>
        <mass>0.185257</mass>
        <inertia>
          <ixx>0.00055489</ixx>
          <ixy>-4.242e-05</ixy>
          <ixz>0</ixz>
          <iyy>0.00027917</iyy>
          <iyz>-1.75e-06</iyz>
          <izz>0.00081028</izz>
        </inertia>
      </inertial>
      <collision name='leg_r_link1_collision'>
        <pose frame=''>0 0 0 0 -0 0</pose>
        <geometry>
          <mesh>
            <scale>1 1 1</scale>
            <uri>model://ginko_description/meshes/stl/link03_r_leg01.stl</uri>
          </mesh>
        </geometry>
        <surface>
          <contact>
            <ode>
              <kp>1e+06</kp>
              <kd>100</kd>
              <max_vel>3</max_vel>
              <min_depth>0.0001</min_depth>
            </ode>
          </contact>
          <friction>
            <ode>
              <mu>0.1</mu>
            </ode>
          </friction>
        </surface>
        <max_contacts>5</max_contacts>
      </collision>
      <visual name='leg_r_link1_visual'>
        <pose frame=''>0 0 0 0 -0 0</pose>
        <geometry>
          <mesh>
            <scale>1 1 1</scale>
            <uri>model://ginko_description/meshes/obj/link03_r_leg01.obj</uri>
          </mesh>
        </geometry>
        <material>
          <script>
            <uri>__default__</uri>
            <name>__default__</name>
          </script>
        </material>
      </visual>
      <gravity>1</gravity>
      <velocity_decay>
        <linear>0.001</linear>
        <angular>0.001</angular>
      </velocity_decay>
      <self_collide>0</self_collide>
    </link>
    <joint name='leg_r_joint1' type='revolute'>
      <child>leg_r_link1</child>
      <parent>leg_r_link0</parent>
      <axis>
        <xyz>0 1 0</xyz>
        <limit>
          <lower>-0.7854</lower>
          <upper>1.3</upper>
          <effort>1000</effort>
          <velocity>10</velocity>
        </limit>
        <dynamics>
          <damping>0.1</damping>
          <friction>0.1</friction>
          <spring_reference>0</spring_reference>
          <spring_stiffness>0</spring_stiffness>
        </dynamics>
        <use_parent_model_frame>1</use_parent_model_frame>
      </axis>
    </joint>
    <link name='leg_r_link3'>
      <pose frame=''>0.073611 -0.0175 -0.159711 0 -0 0</pose>
      <inertial>
        <pose frame=''>0.003934 -0.023642 -0.0193 0 -0 0</pose>
        <mass>0.0178118</mass>
        <inertia>
          <ixx>1.301e-05</ixx>
          <ixy>-8e-08</ixy>
          <ixz>0</ixz>
          <iyy>7e-06</iyy>
          <iyz>0</iyz>
          <izz>1.388e-05</izz>
        </inertia>
      </inertial>
      <collision name='leg_r_link3_collision'>
        <pose frame=''>0 0 0 0 -0 0</pose>
        <geometry>
          <mesh>
            <scale>1 1 1</scale>
            <uri>model://ginko_description/meshes/stl/link05_r_knee.stl</uri>
          </mesh>
        </geometry>
        <surface>
          <contact>
            <ode>
              <kp>1e+06</kp>
              <kd>100</kd>
              <max_vel>3</max_vel>
              <min_depth>0.0001</min_depth>
            </ode>
          </contact>
          <friction>
            <ode>
              <mu>0.1</mu>
            </ode>
          </friction>
        </surface>
        <max_contacts>5</max_contacts>
      </collision>
      <visual name='leg_r_link3_visual'>
        <pose frame=''>0 0 0 0 -0 0</pose>
        <geometry>
          <mesh>
            <scale>1 1 1</scale>
            <uri>model://ginko_description/meshes/obj/link05_r_knee.obj</uri>
          </mesh>
        </geometry>
        <material>
          <script>
            <uri>__default__</uri>
            <name>__default__</name>
          </script>
        </material>
      </visual>
      <gravity>1</gravity>
      <velocity_decay>
        <linear>0.001</linear>
        <angular>0.001</angular>
      </velocity_decay>
      <self_collide>0</self_collide>
    </link>
    <joint name='leg_r_joint3' type='revolute'>
      <child>leg_r_link3</child>
      <parent>leg_r_link1</parent>
      <axis>
        <xyz>0 -1 0</xyz>
        <limit>
          <lower>-0.7854</lower>
          <upper>1.3</upper>
          <effort>1000</effort>
          <velocity>10</velocity>
        </limit>
        <dynamics>
          <damping>0.1</damping>
          <friction>0.1</friction>
          <spring_reference>0</spring_reference>
          <spring_stiffness>0</spring_stiffness>
        </dynamics>
        <use_parent_model_frame>1</use_parent_model_frame>
      </axis>
    </joint>
    <link name='leg_r_link4'>
      <pose frame=''>0.073611 -0.0175 -0.198311 3.14159 0.785393 3.14159</pose>
      <inertial>
        <pose frame=''>0.05 -0.017191 0.000681 0 -0 0</pose>
        <mass>0.185257</mass>
        <inertia>
          <ixx>0.00055489</ixx>
          <ixy>-4.242e-05</ixy>
          <ixz>0</ixz>
          <iyy>0.00027917</iyy>
          <iyz>-1.75e-06</iyz>
          <izz>0.00081028</izz>
        </inertia>
      </inertial>
      <collision name='leg_r_link4_collision'>
        <pose frame=''>0 0 0 0 -0 0</pose>
        <geometry>
          <mesh>
            <scale>1 1 1</scale>
            <uri>model://ginko_description/meshes/stl/link03_r_leg01.stl</uri>
          </mesh>
        </geometry>
      </collision>
      <visual name='leg_r_link4_visual'>
        <pose frame=''>0 0 0 0 -0 0</pose>
        <geometry>
          <mesh>
            <scale>1 1 1</scale>
            <uri>model://ginko_description/meshes/obj/link03_r_leg01.obj</uri>
          </mesh>
        </geometry>
      </visual>
    </link>
    <joint name='leg_r_joint4' type='revolute'>
      <child>leg_r_link4</child>
      <parent>leg_r_link3</parent>
      <axis>
        <xyz>0 1 0</xyz>
        <limit>
          <lower>-1.3</lower>
          <upper>0.7854</upper>
          <effort>1000</effort>
          <velocity>10</velocity>
        </limit>
        <dynamics>
          <damping>0.1</damping>
          <friction>0.1</friction>
          <spring_reference>0</spring_reference>
          <spring_stiffness>0</spring_stiffness>
        </dynamics>
        <use_parent_model_frame>1</use_parent_model_frame>
      </axis>
    </joint>
    <link name='leg_r_link6'>
      <pose frame=''>0.002899 -0.0175 -0.269021 0 -0 0</pose>
      <inertial>
        <pose frame=''>-0.041661 -0.024639 -0.025863 0 -0 0</pose>
        <mass>0.087992</mass>
        <inertia>
          <ixx>2.815e-05</ixx>
          <ixy>4.1e-07</ixy>
          <ixz>9.8e-06</ixz>
          <iyy>6.846e-05</iyy>
          <iyz>2.6e-07</iyz>
          <izz>6.529e-05</izz>
        </inertia>
      </inertial>
      <collision name='leg_r_link6_collision'>
        <pose frame=''>0 0 0 0 -0 0</pose>
        <geometry>
          <mesh>
            <scale>1 1 1</scale>
            <uri>model://ginko_description/meshes/stl/link06_r_toe01.stl</uri>
          </mesh>
        </geometry>
      </collision>
      <visual name='leg_r_link6_visual'>
        <pose frame=''>0 0 0 0 -0 0</pose>
        <geometry>
          <mesh>
            <scale>1 1 1</scale>
            <uri>model://ginko_description/meshes/obj/link06_r_toe01.obj</uri>
          </mesh>
        </geometry>
      </visual>
    </link>
    <joint name='leg_r_joint6' type='revolute'>
      <child>leg_r_link6</child>
      <parent>leg_r_link4</parent>
      <axis>
        <xyz>0 -1 0</xyz>
        <limit>
          <lower>-1.3</lower>
          <upper>0.7854</upper>
          <effort>1000</effort>
          <velocity>10</velocity>
        </limit>
        <dynamics>
          <damping>0.1</damping>
          <friction>0.1</friction>
          <spring_reference>0</spring_reference>
          <spring_stiffness>0</spring_stiffness>
        </dynamics>
        <use_parent_model_frame>1</use_parent_model_frame>
      </axis>
    </joint>
    <link name='leg_r_link7'>
      <pose frame=''>-0.025101 -0.04225 -0.308121 0 -0 0</pose>
      <inertial>
        <pose frame=''>0.026588 -1e-06 -0.017825 0 -0 0</pose>
        <mass>0.1092</mass>
        <inertia>
          <ixx>3.853e-05</ixx>
          <ixy>0</ixy>
          <ixz>-4.79e-06</ixz>
          <iyy>5.192e-05</iyy>
          <iyz>0</iyz>
          <izz>3.521e-05</izz>
        </inertia>
      </inertial>
      <collision name='leg_r_link7_collision'>
        <pose frame=''>0 0 0 0 -0 0</pose>
        <geometry>
          <mesh>
            <scale>1 1 1</scale>
            <uri>model://ginko_description/meshes/stl/link07_r_toe02.stl</uri>
          </mesh>
        </geometry>
      </collision>
      <visual name='leg_r_link7_visual'>
        <pose frame=''>0 0 0 0 -0 0</pose>
        <geometry>
          <mesh>
            <scale>1 1 1</scale>
            <uri>model://ginko_description/meshes/obj/link07_r_toe02.obj</uri>
          </mesh>
        </geometry>
      </visual>
    </link>
    <joint name='leg_r_joint7' type='revolute'>
      <child>leg_r_link7</child>
      <parent>leg_r_link6</parent>
      <axis>
        <xyz>-1 0 0</xyz>
        <limit>
          <lower>-1.6</lower>
          <upper>1.6</upper>
          <effort>1000</effort>
          <velocity>10</velocity>
        </limit>
        <dynamics>
          <spring_reference>0</spring_reference>
          <spring_stiffness>0</spring_stiffness>
        </dynamics>
        <use_parent_model_frame>1</use_parent_model_frame>
      </axis>
    </joint>
    <link name='leg_r_link8'>
      <pose frame=''>0.009099 -0.04225 -0.348121 0 -0 0</pose>
      <inertial>
        <pose frame=''>0 0 -0.002693 0 -0 0</pose>
        <mass>0.0536311</mass>
        <inertia>
          <ixx>2.877e-05</ixx>
          <ixy>0</ixy>
          <ixz>0</ixz>
          <iyy>7.083e-05</iyy>
          <iyz>-0</iyz>
          <izz>9.934e-05</izz>
        </inertia>
      </inertial>
      <collision name='leg_r_link8_collision'>
        <pose frame=''>0 0 -0.003 0 -0 0</pose>
        <geometry>
          <box>
            <size>0.128 0.08 0.006</size>
          </box>
        </geometry>
      </collision>
      <visual name='leg_r_link8_visual'>
        <pose frame=''>0 0 0 0 -0 0</pose>
        <geometry>
          <mesh>
            <scale>1 1 1</scale>
            <uri>model://ginko_description/meshes/obj/link08_r_toe03.obj</uri>
          </mesh>
        </geometry>
      </visual>
    </link>
    <joint name='leg_r_joint8' type='revolute'>
      <child>leg_r_link8</child>
      <parent>leg_r_link7</parent>
      <axis>
        <xyz>0 0 1</xyz>
        <limit>
          <lower>-2.6</lower>
          <upper>2.6</upper>
          <effort>1000</effort>
          <velocity>10</velocity>
        </limit>
        <dynamics>
          <spring_reference>0</spring_reference>
          <spring_stiffness>0</spring_stiffness>
        </dynamics>
        <use_parent_model_frame>1</use_parent_model_frame>
      </axis>
    </joint>
    <link name='leg_r_link5'>
      <pose frame=''>0.052311 -0.0175 -0.186261 3.14159 0.785393 3.14159</pose>
      <inertial>
        <pose frame=''>0.05 -0.024951 -0.004912 0 -0 0</pose>
        <mass>0.0164664</mass>
        <inertia>
          <ixx>6.4e-06</ixx>
          <ixy>0</ixy>
          <ixz>0</ixz>
          <iyy>1.642e-05</iyy>
          <iyz>0</iyz>
          <izz>2.264e-05</izz>
        </inertia>
      </inertial>
      <collision name='leg_r_link5_collision'>
        <pose frame=''>0 0 0 0 -0 0</pose>
        <geometry>
          <mesh>
            <scale>1 1 1</scale>
            <uri>model://ginko_description/meshes/stl/link04_r_leg02.stl</uri>
          </mesh>
        </geometry>
      </collision>
      <visual name='leg_r_link5_visual'>
        <pose frame=''>0 0 0 0 -0 0</pose>
        <geometry>
          <mesh>
            <scale>1 1 1</scale>
            <uri>model://ginko_description/meshes/obj/link04_r_leg02.obj</uri>
          </mesh>
        </geometry>
      </visual>
    </link>
    <joint name='leg_r_joint5' type='revolute'>
      <child>leg_r_link5</child>
      <parent>leg_r_link3</parent>
      <axis>
        <xyz>0 1 0</xyz>
        <limit>
          <lower>-1.3</lower>
          <upper>0.7854</upper>
          <effort>0</effort>
          <velocity>10</velocity>
        </limit>
        <dynamics>
          <spring_reference>0</spring_reference>
          <spring_stiffness>0</spring_stiffness>
        </dynamics>
        <use_parent_model_frame>1</use_parent_model_frame>
      </axis>
    </joint>
    <link name='dummy2_leg_r_link6'>
      <pose frame=''>-0.018401 -0.0175 -0.256971 0 -0 0</pose>
      <inertial>
        <pose frame=''>-0.021 0 0.012 0 -0 0</pose>
        <mass>1e-05</mass>
        <inertia>
          <ixx>1e-08</ixx>
          <ixy>0</ixy>
          <ixz>0</ixz>
          <iyy>1e-08</iyy>
          <iyz>0</iyz>
          <izz>1e-08</izz>
        </inertia>
      </inertial>
    </link>
    <joint name='close_leg_r_joint1' type='revolute'>
      <child>dummy2_leg_r_link6</child>
      <parent>leg_r_link5</parent>
      <axis>
        <xyz>0 -1 0</xyz>
        <limit>
          <lower>-1.3</lower>
          <upper>0.7854</upper>
          <effort>0</effort>
          <velocity>10</velocity>
        </limit>
        <dynamics>
          <spring_reference>0</spring_reference>
          <spring_stiffness>0</spring_stiffness>
        </dynamics>
        <use_parent_model_frame>1</use_parent_model_frame>
      </axis>
    </joint>
    <link name='leg_r_spring1_link0'>
      <pose frame=''>0.073611 -0.0755 -0.198311 3.14159 0.567568 3.14159</pose>
      <inertial>
        <pose frame=''>0.030917 0 0 3.14159 1.00323 3.14159</pose>
        <mass>0.00143865</mass>
        <inertia>
          <ixx>1e-08</ixx>
          <ixy>0</ixy>
          <ixz>0</ixz>
          <iyy>6e-07</iyy>
          <iyz>0</iyz>
          <izz>6e-07</izz>
        </inertia>
      </inertial>
      <collision name='leg_r_spring1_link0_collision'>
        <pose frame=''>0 0 0 0 -0 0</pose>
        <geometry>
          <mesh>
            <scale>1 1 1</scale>
            <uri>model://ginko_description/meshes/stl/spring1.stl</uri>
          </mesh>
        </geometry>
      </collision>
      <visual name='leg_r_spring1_link0_visual'>
        <pose frame=''>0 0 0 0 -0 0</pose>
        <geometry>
          <mesh>
            <scale>1 1 1</scale>
            <uri>model://ginko_description/meshes/stl/spring1.stl</uri>
          </mesh>
        </geometry>
      </visual>
    </link>
    <joint name='leg_r_spring1_joint0' type='revolute'>
      <child>leg_r_spring1_link0</child>
      <parent>leg_r_link3</parent>
      <axis>
        <xyz>0 -1 0</xyz>
        <limit>
          <lower>-3.14159</lower>
          <upper>3.14159</upper>
          <effort>0</effort>
          <velocity>10</velocity>
        </limit>
        <dynamics>
          <spring_reference>0</spring_reference>
          <spring_stiffness>0</spring_stiffness>
        </dynamics>
        <use_parent_model_frame>1</use_parent_model_frame>
      </axis>
    </joint>
    <link name='leg_r_spring1_link1'>
      <pose frame=''>-0.0184 -0.0755 -0.256971 0 -0.567567 0</pose>
      <inertial>
        <pose frame=''>0.030917 0 0 0 -0 0</pose>
        <mass>0.00143865</mass>
        <inertia>
          <ixx>1e-08</ixx>
          <ixy>0</ixy>
          <ixz>0</ixz>
          <iyy>6e-07</iyy>
          <iyz>0</iyz>
          <izz>6e-07</izz>
        </inertia>
      </inertial>
      <collision name='leg_r_spring1_link1_collision'>
        <pose frame=''>0 0 0 0 -0 0</pose>
        <geometry>
          <mesh>
            <scale>1 1 1</scale>
            <uri>model://ginko_description/meshes/stl/spring2.stl</uri>
          </mesh>
        </geometry>
      </collision>
      <visual name='leg_r_spring1_link1_visual'>
        <pose frame=''>0 0 0 0 -0 0</pose>
        <geometry>
          <mesh>
            <scale>1 1 1</scale>
            <uri>model://ginko_description/meshes/stl/spring2.stl</uri>
          </mesh>
        </geometry>
      </visual>
    </link>
    <joint name='spring1_leg_r_joint' type='prismatic'>
      <child>leg_r_spring1_link1</child>
      <parent>leg_r_spring1_link0</parent>
      <axis>
        <xyz>0.843211 0 0.537582</xyz>
        <limit>
          <lower>-0.035</lower>
          <upper>0.055</upper>
          <effort>1000</effort>
          <velocity>10</velocity>
        </limit>
        <dynamics>
          <damping>0</damping>
          <friction>0</friction>
          <spring_reference>0</spring_reference>
          <spring_stiffness>0</spring_stiffness>
        </dynamics>
        <use_parent_model_frame>1</use_parent_model_frame>
      </axis>
    </joint>
    <link name='dummy3_leg_r_link6'>
      <pose frame=''>-0.0184 -0.0755 -0.256971 0 -0.567567 0</pose>
      <inertial>
        <pose frame=''>-0.021 -0.058 0.012 0 -0 0</pose>
        <mass>1e-05</mass>
        <inertia>
          <ixx>1e-08</ixx>
          <ixy>0</ixy>
          <ixz>0</ixz>
          <iyy>1e-08</iyy>
          <iyz>0</iyz>
          <izz>1e-08</izz>
        </inertia>
      </inertial>
    </link>
    <joint name='close_leg_r_spring1_joint2' type='revolute'>
      <child>dummy3_leg_r_link6</child>
      <parent>leg_r_spring1_link1</parent>
      <axis>
        <xyz>-0 -1 0</xyz>
        <limit>
          <lower>-3.14159</lower>
          <upper>3.14159</upper>
          <effort>0</effort>
          <velocity>10</velocity>
        </limit>
        <dynamics>
          <spring_reference>0</spring_reference>
          <spring_stiffness>0</spring_stiffness>
        </dynamics>
        <use_parent_model_frame>1</use_parent_model_frame>
      </axis>
    </joint>
    <link name='leg_r_link2'>
      <pose frame=''>-0.0184 -0.0175 -0.10105 0 0.7854 0</pose>
      <inertial>
        <pose frame=''>0.05 -0.024951 -0.004912 0 -0 0</pose>
        <mass>0.0164664</mass>
        <inertia>
          <ixx>6.4e-06</ixx>
          <ixy>0</ixy>
          <ixz>0</ixz>
          <iyy>1.642e-05</iyy>
          <iyz>0</iyz>
          <izz>2.264e-05</izz>
        </inertia>
      </inertial>
      <collision name='leg_r_link2_collision'>
        <pose frame=''>0 0 0 0 -0 0</pose>
        <geometry>
          <mesh>
            <scale>1 1 1</scale>
            <uri>model://ginko_description/meshes/stl/link04_r_leg02.stl</uri>
          </mesh>
        </geometry>
        <surface>
          <contact>
            <ode>
              <kp>1e+06</kp>
              <kd>100</kd>
              <max_vel>3</max_vel>
              <min_depth>0.0001</min_depth>
            </ode>
          </contact>
          <friction>
            <ode>
              <mu>0.1</mu>
            </ode>
          </friction>
        </surface>
        <max_contacts>5</max_contacts>
      </collision>
      <visual name='leg_r_link2_visual'>
        <pose frame=''>0 0 0 0 -0 0</pose>
        <geometry>
          <mesh>
            <scale>1 1 1</scale>
            <uri>model://ginko_description/meshes/obj/link04_r_leg02.obj</uri>
          </mesh>
        </geometry>
        <material>
          <script>
            <uri>__default__</uri>
            <name>__default__</name>
          </script>
        </material>
      </visual>
      <gravity>1</gravity>
      <velocity_decay>
        <linear>0.001</linear>
        <angular>0.001</angular>
      </velocity_decay>
      <self_collide>0</self_collide>
    </link>
    <joint name='leg_r_joint2' type='revolute'>
      <child>leg_r_link2</child>
      <parent>leg_r_link0</parent>
      <axis>
        <xyz>0 1 0</xyz>
        <limit>
          <lower>-0.7854</lower>
          <upper>1.3</upper>
          <effort>1000</effort>
          <velocity>10</velocity>
        </limit>
        <dynamics>
          <spring_reference>0</spring_reference>
          <spring_stiffness>0</spring_stiffness>
        </dynamics>
        <use_parent_model_frame>1</use_parent_model_frame>
      </axis>
    </joint>
    <link name='dummy0_leg_r_link3'>
      <pose frame=''>0.052311 -0.0175 -0.171761 0 -0 0</pose>
      <inertial>
        <pose frame=''>-0.021 0 -0.012 0 -0 0</pose>
        <mass>1e-05</mass>
        <inertia>
          <ixx>1e-08</ixx>
          <ixy>0</ixy>
          <ixz>0</ixz>
          <iyy>1e-08</iyy>
          <iyz>0</iyz>
          <izz>1e-08</izz>
        </inertia>
      </inertial>
    </link>
    <joint name='close_leg_r_joint0' type='revolute'>
      <child>dummy0_leg_r_link3</child>
      <parent>leg_r_link2</parent>
      <axis>
        <xyz>0 -1 0</xyz>
        <limit>
          <lower>-0.7854</lower>
          <upper>1.3</upper>
          <effort>1000</effort>
          <velocity>10</velocity>
        </limit>
        <dynamics>
          <spring_reference>0</spring_reference>
          <spring_stiffness>0</spring_stiffness>
        </dynamics>
        <use_parent_model_frame>1</use_parent_model_frame>
      </axis>
    </joint>
    <link name='leg_r_spring0_link0'>
      <pose frame=''>-0.0184 -0.0755 -0.10105 0 0.567568 0</pose>
      <inertial>
        <pose frame=''>0.030917 0 0 0 -0 0</pose>
        <mass>0.00143865</mass>
        <inertia>
          <ixx>1e-08</ixx>
          <ixy>0</ixy>
          <ixz>0</ixz>
          <iyy>6e-07</iyy>
          <iyz>0</iyz>
          <izz>6e-07</izz>
        </inertia>
      </inertial>
      <collision name='leg_r_spring0_link0_collision'>
        <pose frame=''>0 0 0 0 -0 0</pose>
        <geometry>
          <mesh>
            <scale>1 1 1</scale>
            <uri>model://ginko_description/meshes/stl/spring1.stl</uri>
          </mesh>
        </geometry>
      </collision>
      <visual name='leg_r_spring0_link0_visual'>
        <pose frame=''>0 0 0 0 -0 0</pose>
        <geometry>
          <mesh>
            <scale>1 1 1</scale>
            <uri>model://ginko_description/meshes/stl/spring1.stl</uri>
          </mesh>
        </geometry>
      </visual>
    </link>
    <joint name='leg_r_spring0_joint0' type='revolute'>
      <child>leg_r_spring0_link0</child>
      <parent>leg_r_link0</parent>
      <axis>
        <xyz>0 -1 0</xyz>
        <limit>
          <lower>-3.14159</lower>
          <upper>3.14159</upper>
          <effort>0</effort>
          <velocity>10</velocity>
        </limit>
        <dynamics>
          <spring_reference>0</spring_reference>
          <spring_stiffness>0</spring_stiffness>
        </dynamics>
        <use_parent_model_frame>1</use_parent_model_frame>
      </axis>
    </joint>
    <link name='leg_r_spring0_link1'>
      <pose frame=''>0.073611 -0.0755 -0.159711 3.14159 -0.567568 -3.14159</pose>
      <inertial>
        <pose frame=''>0.030917 0 0 0 -0 0</pose>
        <mass>0.00143865</mass>
        <inertia>
          <ixx>1e-08</ixx>
          <ixy>0</ixy>
          <ixz>0</ixz>
          <iyy>6e-07</iyy>
          <iyz>0</iyz>
          <izz>6e-07</izz>
        </inertia>
      </inertial>
      <collision name='leg_r_spring0_link1_collision'>
        <pose frame=''>0 0 0 0 -0 0</pose>
        <geometry>
          <mesh>
            <scale>1 1 1</scale>
            <uri>model://ginko_description/meshes/stl/spring2.stl</uri>
          </mesh>
        </geometry>
      </collision>
      <visual name='leg_r_spring0_link1_visual'>
        <pose frame=''>0 0 0 0 -0 0</pose>
        <geometry>
          <mesh>
            <scale>1 1 1</scale>
            <uri>model://ginko_description/meshes/stl/spring2.stl</uri>
          </mesh>
        </geometry>
      </visual>
    </link>
    <joint name='spring0_leg_r_joint' type='prismatic'>
      <child>leg_r_spring0_link1</child>
      <parent>leg_r_spring0_link0</parent>
      <axis>
        <xyz>-0.843211 0 0.537583</xyz>
        <limit>
          <lower>-0.035</lower>
          <upper>0.055</upper>
          <effort>1000</effort>
          <velocity>10</velocity>
        </limit>
        <dynamics>
          <damping>0</damping>
          <friction>0</friction>
          <spring_reference>0</spring_reference>
          <spring_stiffness>0</spring_stiffness>
        </dynamics>
        <use_parent_model_frame>1</use_parent_model_frame>
      </axis>
    </joint>
    <link name='dummy1_leg_r_link3'>
      <pose frame=''>0.073611 -0.0755 -0.159711 3.14159 -0.567568 3.14159</pose>
      <inertial>
        <pose frame=''>0 -0.058 0 0 -0 0</pose>
        <mass>1e-05</mass>
        <inertia>
          <ixx>1e-08</ixx>
          <ixy>0</ixy>
          <ixz>0</ixz>
          <iyy>1e-08</iyy>
          <iyz>0</iyz>
          <izz>1e-08</izz>
        </inertia>
      </inertial>
    </link>
    <joint name='close_leg_r_spring0_joint2' type='revolute'>
      <child>dummy1_leg_r_link3</child>
      <parent>leg_r_spring0_link1</parent>
      <axis>
        <xyz>-0 -1 0</xyz>
        <limit>
          <lower>-3.14159</lower>
          <upper>3.14159</upper>
          <effort>0</effort>
          <velocity>10</velocity>
        </limit>
        <dynamics>
          <spring_reference>0</spring_reference>
          <spring_stiffness>0</spring_stiffness>
        </dynamics>
        <use_parent_model_frame>1</use_parent_model_frame>
      </axis>
    </joint>
    <static>0</static>
    <plugin name='gazebo_ros_control' filename='libgazebo_ros_control.so'>
      <robotNamespace>/ginko</robotNamespace>
      <robotSimType>gazebo_ros_control/GinkoRobotHWSim</robotSimType>
      <legacyModeNS>1</legacyModeNS>
    </plugin>
  </model>
</sdf>
