<?xml version="1.0"?>
<robot xmlns:xacro="http://www.ros.org/wiki/xacro">
	<xacro:macro name="arm_l" params="model_mode">
		<!-- shoulder pitch. -->
		<joint name="arm_l_joint0" type="revolute">
		    <parent link="body_link0"/>
			<child link="arm_l_link0"/>
		    <origin xyz="0 0.10683 0.05115" rpy="0 0.3927 0"/>
		    <axis xyz="0 -1 0"/>
			<limit effort="1000.0" lower="-2.6" upper="2.6" velocity="10.0"/>
			<dynamics damping="0.1" friction="0.1"/>
		</joint>
		<link name="arm_l_link0">
			<collision>
				<origin xyz="0 0 0" rpy="0 0 0"/>
				<geometry>
					<mesh filename="package://ginko_description/meshes/stl/link09_l_arm01.stl"/>
				</geometry>
			</collision>
			<visual>
				<origin xyz="0 0 0" rpy="0 0 0"/>
				<geometry>
					<mesh filename="package://ginko_description/meshes/obj/link09_l_arm01.obj"/>
				</geometry>
			</visual>
			<inertial>
				<mass value="0.01356014"/>
				<origin xyz="-0.01125790 0.00529265 0.00000000" rpy="0 0 0"/>
				<inertia
					ixx="0.00000235"
					ixy="0.00000004" iyy="0.00001670"
					ixz="0.00000000" iyz="0.00000000" izz="0.00001606"/>
			</inertial>
		</link>

		<!-- shoulder roll -->
		<joint name="arm_l_joint1" type="revolute">
			<parent link="arm_l_link0"/>
			<child  link="arm_l_link1"/>
			<origin xyz="0.035 0.0246 0" rpy="1.1781 0 0"/>
			<axis xyz="1 0 0"/>
			<limit effort="1000.0" lower="-1.18" upper="1.5" velocity="10.0"/>
			<dynamics damping="0.1" friction="0.1"/>
		</joint>
		<link name="arm_l_link1">
			<collision>
				<origin xyz="0 0 0" rpy="0 0 0"/>
	    		<geometry>                                                              
					<mesh filename="package://ginko_description/meshes/stl/link10_l_arm02.stl"/>
	    		</geometry>
			</collision>
			<visual>
				<origin xyz="0 0 0" rpy="0 0 0"/>
				<geometry>
					<mesh filename="package://ginko_description/meshes/obj/link10_l_arm02.obj"/>
				</geometry>
			</visual>
			<inertial>
				<mass value="0.33139947"/>
				<origin xyz="-0.02612786 0.02650564 -0.06333369" rpy="0 0 0"/>
				<inertia
					ixx="0.00115128"
					ixy="0.00015366" iyy="0.00113572"
					ixz="-0.00031848" iyz="-0.00037104" izz="0.00064743"/>
			</inertial>
		</link>
		<joint name="arm_l_joint1_rev" type="revolute">
			<parent link="arm_l_link0"/>
			<child  link="dummy0_arm_l_link1"/>
			<origin xyz="-0.0562 0.0246 0" rpy="1.1781 0 0"/>
			<axis xyz="-1 0 0"/>
			<limit effort="1000.0" lower="-1.5" upper="1.18" velocity="10.0"/>
			<dynamics damping="0.0" friction="0.0"/>
		</joint>
		<link name="dummy0_arm_l_link1">
			<inertial>
				<mass value="0.00001"/>
				<origin xyz="-0.0912 0 0" rpy="0 0 0"/>
				<inertia
					ixx="0.00000001"
					ixy="0.00000000" iyy="0.00000001"
					ixz="0.00000000" iyz="0.00000000" izz="0.00000001"/>
			</inertial>
		</link>

		<!-- scissors -->
		<joint name="arm_l_joint2" type="revolute">
	    	<parent link="arm_l_link1"/>
	    	<child  link="arm_l_link2"/>
	    	<origin xyz="0.0092 0.0547 -0.11295" rpy="0 0.7854 0"/>
	    	<axis xyz="0 1 0"/>
	    	<limit effort="1000.0" lower="-2.36" upper="2.36" velocity="10.0"/>
			<dynamics damping="0.1" friction="0.1"/>
		</joint>
		<link name="arm_l_link2">
	    	<collision>
				<origin xyz="0 0 0" rpy="0 0 0"/>
	    		<geometry>                                                              
					<mesh filename="package://ginko_description/meshes/stl/link11_l_scissor01.stl"/>
	    		</geometry>
			</collision>
			<visual>
				<origin xyz="0 0 0" rpy="0 0 0"/>
				<geometry>
					<mesh filename="package://ginko_description/meshes/obj/link11_l_scissor01.obj"/>
				</geometry>
			</visual>
			<inertial>
				<mass value="0.03287850"/>
				<origin xyz="0.08234859 -0.030246866 0.00514112" rpy="0 0 0"/>
				<inertia
					ixx="0.00002277"
					ixy="-0.00000014" iyy="0.00008197"
					ixz="-0.00000058" iyz="-0.00000001" izz="0.00010105"/>
			</inertial>
		</link>
		<joint name="arm_l_joint3" type="revolute">
	    	<parent link="arm_l_link1"/>
	    	<child  link="arm_l_link3"/>
	    	<origin xyz="0.0092 -0.0018 -0.11295" rpy="0 0.7854 0"/>
	    	<axis xyz="0 1 0"/>
	    	<limit effort="1000.0" lower="-2.36" upper="2.36" velocity="10.0"/>
			<dynamics damping="0.1" friction="0.1"/>
		</joint>
		<link name="arm_l_link3">
	    	<collision>
				<origin xyz="0 0 0" rpy="0 0 0"/>
	    		<geometry>                                                              
					<mesh filename="package://ginko_description/meshes/stl/link12_l_scissor02.stl"/>
	    		</geometry>
			</collision>
			<visual>
				<origin xyz="0 0 0" rpy="0 0 0"/>
				<geometry>
					<mesh filename="package://ginko_description/meshes/obj/link12_l_scissor02.obj"/>
				</geometry>
			</visual>
			<inertial>
				<mass value="0.02936110"/>
				<origin xyz="0.07807033 0.02515230 -0.00665437" rpy="0 0 0"/>
				<inertia
					ixx="0.00001452"
					ixy="0.00000023" iyy="0.00006407"
					ixz="-0.00000245" iyz="-0.00000002" izz="0.00008024"/>
			</inertial>
		</link>

	  	<!-- LiDAR -->
		<!-- use zero-limited revolute joint for fixed joint (SDF) -->
		<joint name="arm_l_urg_joint" type="revolute">
	    	<parent link="arm_l_link1"/>
	    	<child  link="arm_l_urg_link"/>
	    	<origin xyz="-0.0456 -0.01715 -0.06795" rpy="0 1.57 -1.57"/>
	    	<axis xyz="0 0 1"/>
	    	<limit effort="0.0" lower="0.0" upper="0.0" velocity="0.0"/>
			<dynamics damping="0.1" friction="0.1"/>
		</joint>
		<link name="arm_l_urg_link">
	    	<collision>
				<origin xyz="0 0 0" rpy="0 0 0"/>
	    		<geometry>                                                              
					<mesh filename="package://ginko_description/meshes/stl/urg.stl"/>
	    		</geometry>
			</collision>
			<visual>
				<origin xyz="0 0 0" rpy="0 0 0"/>
				<geometry>
					<mesh filename="package://ginko_description/meshes/obj/urg.obj"/>
				</geometry>
			</visual>
			<inertial>
				<mass value="0.16705492"/>
				<origin xyz="-0.00014579 0.00000831 -0.02360505" rpy="0 0 0"/>
				<inertia
					ixx="0.00008801"
					ixy="0.00000000" iyy="0.00008854"
					ixz="-0.00000049" iyz="-0.00000004" izz="0.00006019"/>
			</inertial>
		</link>
	</xacro:macro>
</robot>
