<?xml version="1.0"?>
<robot xmlns:xacro="http://www.ros.org/wiki/xacro">
	<xacro:macro name="leg_l" params="model_mode">
		<!-- Link conencts from body. Femoral first. -->
		<joint name="leg_l_joint0" type="revolute">
		    <parent link="body_link1"/>
			<child link="leg_l_link0"/>
			<origin xyz="-0.0404 0.0 -0.0409" rpy="0 0 0"/>
		    <axis xyz="-1 0 0"/>
			<limit effort="1000.0" lower="-0.8" upper="1.0" velocity="10.0"/>
			<dynamics damping="0.1" friction="0.1"/>
		</joint>
		<link name="leg_l_link0">
			<collision>
				<origin xyz="0 0 0" rpy="0 0 0"/>
				<geometry>                                                              
					<mesh filename="package://ginko_description/meshes/stl/link02_l_femoral.stl"/>
				</geometry>
			</collision>
			<visual>
				<origin xyz="0 0 0" rpy="0 0 0"/>
				<geometry>
					<mesh filename="package://ginko_description/meshes/obj/link02_l_femoral.obj"/>
				</geometry>
			</visual>
			<inertial>
				<mass value="0.03433352"/>
				<origin xyz="0.02930795 0.03723759 -0.02605386" rpy="0 0 0"/>
				<inertia
					ixx="0.00002443"
					ixy="-0.00000021" iyy="0.00002287"
					ixz="-0.00000021" iyz="-0.00000391" izz="0.00002983"/>
			</inertial>
		</link>

		<!-- parallel link (upper-1st) -->
		<joint name="leg_l_joint1" type="revolute">
			<parent link="leg_l_link0"/>
			<child  link="leg_l_link1"/>
			<origin xyz="0.0433 0.0175 -0.0481" rpy="0 0.7854 0"/>
			<axis xyz="0 -1 0"/>
			<limit effort="1000.0" lower="-1.3" upper="0.7854" velocity="10.0"/>
			<dynamics damping="0.1" friction="0.1"/>
		</joint>
		<link name="leg_l_link1">
			<collision>
				<origin xyz="0 0 0" rpy="0 0 0"/>
	    		<geometry>                                                              
					<mesh filename="package://ginko_description/meshes/stl/link03_l_leg01.stl"/>
	    		</geometry>
			</collision>
			<visual>
				<origin xyz="0 0 0" rpy="0 0 0"/>
				<geometry>
					<mesh filename="package://ginko_description/meshes/obj/link03_l_leg01.obj"/>
				</geometry>
			</visual>
			<inertial>
				<mass value="0.18525692"/>
				<origin xyz="0.05000000 0.03285059 0.00068146" rpy="0 0 0"/>
				<inertia
					ixx="0.00041331"
					ixy="-0.00003605" iyy="0.00027917"
					ixz="-0.00000000" iyz="-0.00000184" izz="0.00066510"/>
			</inertial>
		</link>
		<joint name="leg_l_joint3" type="revolute">
	    	<parent link="leg_l_link1"/>
	    	<child  link="leg_l_link3"/>
	    	<origin xyz="0.1 0.0 0.0" rpy="0 -0.7854 0"/>
	    	<axis xyz="0 1 0"/>
			<limit effort="1000.0" lower="-1.3" upper="0.7854" velocity="10.0"/>
			<dynamics damping="0.1" friction="0.1"/>
			<xacro:if value="${model_mode=='rviz'}">
				<mimic joint="leg_l_joint1" multiplier="1" offset="0"/>
			</xacro:if>
	  	</joint>

		<!-- parallel link (upper-2nd) -->
		<joint name="leg_l_joint2" type="revolute">
			<parent link="leg_l_link0"/>
			<child  link="leg_l_link2"/>
			<origin xyz="0.022 0.0175 -0.06015" rpy="0 0.7854 0"/>
			<axis xyz="0 -1 0"/>
			<limit effort="1000.0" lower="-1.3" upper="0.7854" velocity="10.0"/>
			<dynamics damping="0.1" friction="0.1"/>
			<xacro:if value="${model_mode=='rviz'}">
				<mimic joint="leg_l_joint1" multiplier="1" offset="0"/> 
    		</xacro:if>
		</joint>
		<link name="leg_l_link2">
	    	<collision>
				<origin xyz="0 0 0" rpy="0 0 0"/>
	    		<geometry>                                                              
					<mesh filename="package://ginko_description/meshes/stl/link04_l_leg02.stl"/>
	    		</geometry>
			</collision>
			<visual>
				<origin xyz="0 0 0" rpy="0 0 0"/>
				<geometry>
					<mesh filename="package://ginko_description/meshes/obj/link04_l_leg02.obj"/>
				</geometry>
			</visual>
			<inertial>
				<mass value="0.01646643"/>
				<origin xyz="0.05000000 0.02495100 -0.00491150" rpy="0 0 0"/>
				<inertia
					ixx="0.00000640"
					ixy="0.00000000" iyy="0.00001642"
					ixz="0.00000000" iyz="0.00000000" izz="0.00002264"/>
			</inertial>
		</link>
		<joint name="close_leg_l_joint0" type="revolute">
			<parent link="leg_l_link2"/>
			<child  link="dummy0_leg_l_link3"/>
			<origin xyz="0.1 0.0 0.0" rpy="0 -0.7854 0"/>
			<axis xyz="0 1 0"/>
			<limit effort="1000.0" lower="-1.3" upper="0.7854" velocity="10.0"/>
			<dynamics damping="0.0" friction="0.0"/>
			<xacro:if value="${model_mode=='rviz'}">
				<mimic joint="leg_l_joint1" multiplier="1" offset="0"/>
			</xacro:if>
		</joint>
		<link name="dummy0_leg_l_link3">
			<inertial>
				<mass value="0.00001"/>
				<origin xyz="-0.021 0 -0.012" rpy="0 0 0"/>
				<inertia
					ixx="0.00000001"
					ixy="0.00000000" iyy="0.00000001"
					ixz="0.00000000" iyz="0.00000000" izz="0.00000001"/>
			</inertial>
		</link>

		<!-- knee -->
		<link name="leg_l_link3">
	    	<collision>
				<origin xyz="0 0 0" rpy="0 0 0"/>
	    		<geometry>
					<mesh filename="package://ginko_description/meshes/stl/link05_l_knee.stl"/>
	    		</geometry>
			</collision>
			<visual>
				<origin xyz="0 0 0" rpy="0 0 0"/>
				<geometry>
					<mesh filename="package://ginko_description/meshes/obj/link05_l_knee.obj"/>
				</geometry>
			</visual>
			<inertial>
				<mass value="0.01781176"/>
				<origin xyz="0.00393357 0.02364163 -0.01930000" rpy="0 0 0"/>
				<inertia
					ixx="0.00001301"
					ixy="0.00000008" iyy="0.00000700"
					ixz="0.00000000" iyz="0.00000000" izz="0.00001388"/>
			</inertial>
		</link>

	  	<!-- spring -->
		<xacro:if value="${model_mode!='rviz'}">
			<joint name="leg_l_spring0_joint0" type="revolute">
		    	<parent link="leg_l_link0"/>
		    	<child  link="leg_l_spring0_link0"/>
		    	<origin xyz="0.022 0.0755 -0.06015" rpy="0 0.56756754 0"/>
		    	<axis xyz="0 -1 0"/>
				<dynamics damping="0.0" friction="0.0"/>
		    	<limit effort="0.0" lower="-3.141593" upper="3.141593" velocity="10.0"/>
		  	</joint>
		  	<link name="leg_l_spring0_link0">
		    	<collision>
					<origin xyz="0 0 0" rpy="0 0 0"/>
		    		<geometry>                                                              
						<mesh filename="package://ginko_description/meshes/stl/spring1.stl"/>
		    		</geometry>
				</collision>
		    	<visual>
					<origin xyz="0 0 0" rpy="0 0 0"/>
		    		<geometry>                                                              
						<mesh filename="package://ginko_description/meshes/stl/spring1.stl"/>
		    		</geometry>
					<material name="spring">
						<color rgba="0.5 0.5 0.5 1.0"/>
					</material>
				</visual>
				<inertial>
					<mass value="0.00143865"/>
					<origin xyz="0.03091683 0.0 0.0" rpy="0 0 0"/>
					<inertia
						ixx="0.00000001"
						ixy="0.00000000" iyy="0.00000060"
						ixz="0.00000000" iyz="0.00000000" izz="0.00000060"/>
				</inertial>
			</link>
			<joint name="spring0_leg_l_joint" type="prismatic">
				<parent link="leg_l_spring0_link0"/>
				<child  link="leg_l_spring0_link1"/>
				<origin xyz="0.10911938 0.0 0.0" rpy="0 3.141593 0"/>
				<axis xyz="1 0 0"/>
				<limit effort="1000.0" lower="-0.03" upper="0.06" velocity="10.0"/>
				<dynamics damping="0.0" friction="0.0"/>
			</joint>
		  	<link name="leg_l_spring0_link1">
		    	<collision>
					<origin xyz="0 0 0" rpy="0 0 0"/>
		    		<geometry>                                                              
						<mesh filename="package://ginko_description/meshes/stl/spring2.stl"/>
		    		</geometry>
				</collision>
		    	<visual>
					<origin xyz="0 0 0" rpy="0 0 0"/>
		    		<geometry>                                                              
						<mesh filename="package://ginko_description/meshes/stl/spring2.stl"/>
		    		</geometry>
					<material name="spring">
						<color rgba="0.5 0.5 0.5 1.0"/>
					</material>
				</visual>
				<inertial>
					<mass value="0.00143865"/>
					<origin xyz="0.03091683 0.0 0.0" rpy="0 0 0"/>
					<inertia
						ixx="0.00000001"
						ixy="0.00000000" iyy="0.00000060"
						ixz="0.00000000" iyz="0.00000000" izz="0.00000060"/>
				</inertial>
			</link>
			<joint name="close_leg_l_spring0_joint1" type="revolute">
				<parent link="leg_l_spring0_link1"/>
				<child  link="dummy1_leg_l_link3"/>
				<origin xyz="0 0 0" rpy="0 0 0"/>
				<axis xyz="0 -1 0"/>
				<limit effort="0.0" lower="-3.141593" upper="3.141593" velocity="10.0"/>
				<dynamics damping="0.0" friction="0.0"/>
			</joint>
			<link name="dummy1_leg_l_link3">
				<inertial>
					<mass value="0.00001"/>
					<origin xyz="0 0.058 0" rpy="0 0 0"/>
					<inertia
						ixx="0.00000001"
						ixy="0.00000000" iyy="0.00000001"
						ixz="0.00000000" iyz="0.00000000" izz="0.00000001"/>
				</inertial>
			</link>
		</xacro:if>

		<!-- parallel link (lower-1st) -->
		<joint name="leg_l_joint4" type="revolute">
			<parent link="leg_l_link3"/>
			<child  link="leg_l_link4"/>
			<origin xyz="0 0 -0.0386" rpy="0 2.3562 0"/>
			<axis xyz="0 -1 0"/>
			<limit effort="1000.0" lower="-0.7854" upper="1.3" velocity="10.0"/>
			<dynamics damping="0.1" friction="0.1"/>
		</joint>
		<link name="leg_l_link4">
			<collision>
				<origin xyz="0 0 0" rpy="0 0 0"/>
	    		<geometry>                                                              
					<mesh filename="package://ginko_description/meshes/stl/link03_l_leg01.stl"/>
	    		</geometry>
			</collision>
			<visual>
				<origin xyz="0 0 0" rpy="0 0 0"/>
				<geometry>
					<mesh filename="package://ginko_description/meshes/obj/link03_l_leg01.obj"/>
				</geometry>
			</visual>
			<inertial>
				<mass value="0.18525692"/>
				<origin xyz="0.05000000 0.03285059 0.00068146" rpy="0 0 0"/>
				<inertia
					ixx="0.00041331"
					ixy="-0.00003605" iyy="0.00027917"
					ixz="-0.00000000" iyz="-0.00000184" izz="0.00066510"/>
			</inertial>
		</link>
		<joint name="leg_l_joint6" type="revolute">
	    	<parent link="leg_l_link4"/>
	    	<child  link="leg_l_link6"/>
	    	<origin xyz="0.1 0.0 0.0" rpy="0 -2.3562 0"/>
	    	<axis xyz="0 1 0"/>
			<limit effort="1000.0" lower="-0.7854" upper="1.3" velocity="10.0"/>
			<dynamics damping="0.1" friction="0.1"/>
			<xacro:if value="${model_mode=='rviz'}">
	    		<mimic joint="leg_l_joint4" multiplier="1" offset="0"/> 
			</xacro:if>
		</joint>

		<!-- parallel link (lower-2nd) -->
		<joint name="leg_l_joint5" type="revolute">
			<parent link="leg_l_link3"/>
			<child  link="leg_l_link5"/>
			<origin xyz="-0.0213 0 -0.02655" rpy="0 2.3562 0"/>
			<axis xyz="0 -1 0"/>
			<limit effort="0.0" lower="-0.7854" upper="1.3" velocity="10.0"/>
			<dynamics damping="0.0" friction="0.0"/>
			<xacro:if value="${model_mode=='rviz'}">
				<mimic joint="leg_l_joint4" multiplier="1" offset="0"/>
			</xacro:if>
		</joint>
		<link name="leg_l_link5">
	    	<collision>
				<origin xyz="0 0 0" rpy="0 0 0"/>
	    		<geometry>                                                              
					<mesh filename="package://ginko_description/meshes/stl/link04_l_leg02.stl"/>
	    		</geometry>
			</collision>
			<visual>
				<origin xyz="0 0 0" rpy="0 0 0"/>
				<geometry>
					<mesh filename="package://ginko_description/meshes/obj/link04_l_leg02.obj"/>
				</geometry>
			</visual>
			<inertial>
				<mass value="0.01646643"/>
				<origin xyz="0.05000000 0.02495100 -0.00491150" rpy="0 0 0"/>
				<inertia
					ixx="0.00000640"
					ixy="0.00000000" iyy="0.00001642"
					ixz="0.00000000" iyz="0.00000000" izz="0.00002264"/>
			</inertial>
		</link>
		<joint name="close_leg_l_joint1" type="revolute">
			<parent link="leg_l_link5"/>
			<child  link="dummy2_leg_l_link6"/>
			<origin xyz="0.1 0.0 0.0" rpy="0 -2.3562 0"/>
			<axis xyz="0 1 0"/>
			<limit effort="0.0" lower="-1.3" upper="0.7854" velocity="10.0"/>
			<dynamics damping="0.0" friction="0.0"/>
			<xacro:if value="${model_mode=='rviz'}">
				<mimic joint="leg_l_joint4" multiplier="1" offset="0"/>
			</xacro:if>
		</joint>
		<link name="dummy2_leg_l_link6">
			<inertial>
				<mass value="0.00001"/>
				<origin xyz="-0.021 0 0.012" rpy="0 0 0"/>
				<inertia
					ixx="0.00000001"
					ixy="0.00000000" iyy="0.00000001"
					ixz="0.00000000" iyz="0.00000000" izz="0.00000001"/>
			</inertial>
		</link>

	  	<!-- spring -->
		<xacro:if value="${model_mode!='rviz'}">
			<joint name="leg_l_spring1_joint0" type="revolute">
				<parent link="leg_l_link4"/>
				<child  link="leg_l_spring1_link0"/>
				<origin xyz="0 0.058 0" rpy="0 0.217830624 0"/>
				<axis xyz="0 -1 0"/>
				<limit effort="1000.0" lower="-3.141593" upper="3.141593" velocity="10.0"/>
				<dynamics damping="0.01" friction="0.01"/>
			</joint>
			<link name="leg_l_spring1_link0">
				<collision>
					<origin xyz="0 0 0" rpy="0 0 0"/>
					<geometry>                                                              
						<mesh filename="package://ginko_description/meshes/stl/spring1.stl"/>
					</geometry>
				</collision>
				<visual>
					<origin xyz="0 0 0" rpy="0 0 0"/>
					<geometry>                                                              
						<mesh filename="package://ginko_description/meshes/stl/spring1.stl"/>
					</geometry>
					<material name="spring">
						<color rgba="0.5 0.5 0.5 1.0"/>
					</material>
				</visual>
				<inertial>
					<mass value="0.00143865"/>
					<origin xyz="0.03091683 0.0 0.0" rpy="0 2.138363867 0"/>
					<inertia
						ixx="0.00000001"
						ixy="0.00000000" iyy="0.00000060"
						ixz="0.00000000" iyz="0.00000000" izz="0.00000060"/>
				</inertial>
			</link>
			<joint name="spring1_leg_l_joint" type="prismatic">
				<parent link="leg_l_spring1_link0"/>
				<child  link="leg_l_spring1_link1"/>
				<origin xyz="0.10911938 0.0 0.0" rpy="0 3.141593 0"/>
				<axis xyz="1 0 0"/>
				<limit effort="1000.0" lower="-0.03" upper="0.06" velocity="10.0"/>
				<dynamics damping="0.01" friction="0.01"/>
			</joint>
			<link name="leg_l_spring1_link1">
				<collision>
					<origin xyz="0 0 0" rpy="0 0 0"/>
					<geometry>                                                              
						<mesh filename="package://ginko_description/meshes/stl/spring2.stl"/>
					</geometry>
				</collision>
				<visual>
					<origin xyz="0 0 0" rpy="0 0 0"/>
					<geometry>                                                              
						<mesh filename="package://ginko_description/meshes/stl/spring2.stl"/>
					</geometry>
					<material name="spring">
						<color rgba="0.5 0.5 0.5 1.0"/>
					</material>
				</visual>
				<inertial>
					<mass value="0.00143865"/>
					<origin xyz="0.03091683 0.0 0.0" rpy="0 0 0"/>
					<inertia
						ixx="0.00000001"
						ixy="0.00000000" iyy="0.00000060"
						ixz="0.00000000" iyz="0.00000000" izz="0.00000060"/>
				</inertial>
			</link>
			<joint name="close_leg_l_spring1_joint1" type="revolute">
				<parent link="leg_l_spring1_link1"/>
				<child  link="dummy3_leg_l_link6"/>
				<origin xyz="0 0 0" rpy="0 0 0"/>
				<axis xyz="0 -1 0"/>
				<limit effort="1000.0" lower="-3.141593" upper="3.141593" velocity="10.0"/>
				<dynamics damping="0.01" friction="0.01"/>
			</joint>
			<link name="dummy3_leg_l_link6">
				<inertial>
					<mass value="0.00001"/>
					<origin xyz="-0.021 0.058 0.012" rpy="0 0 0"/>
					<inertia
						ixx="0.00000001"
						ixy="0.00000000" iyy="0.00000001"
						ixz="0.00000000" iyz="0.00000000" izz="0.00000001"/>
				</inertial>
			</link>
		</xacro:if>

		<!-- toe -->
		<link name="leg_l_link6">
			<collision>
				<origin xyz="0 0 0" rpy="0 0 0"/>
				<geometry>
					<mesh filename="package://ginko_description/meshes/stl/link06_l_toe01.stl"/>
				</geometry>
			</collision>
			<visual>
				<origin xyz="0 0 0" rpy="0 0 0"/>
				<geometry>
					<mesh filename="package://ginko_description/meshes/obj/link06_l_toe01.obj"/>
				</geometry>
			</visual>
			<inertial>
				<mass value="0.08799204"/>
				<origin xyz="-0.04166125 0.02463880 -0.02586249" rpy="0 0 0"/>
				<inertia
					ixx="0.00002815"
					ixy="-0.00000041" iyy="0.00006846"
					ixz="0.00000980" iyz="-0.00000026" izz="0.00006529"/>
			</inertial>
		</link>
		<joint name="leg_l_joint7" type="revolute">
	    	<parent link="leg_l_link6"/>
	    	<child  link="leg_l_link7"/>
	    	<origin xyz="-0.028 0.02475 -0.0391" rpy="0 0 0"/>
	    	<axis xyz="-1 0 0"/>
	    	<limit effort="1000.0" lower="-1.6" upper="1.6" velocity="10.0"/>
			<dynamics damping="0.1" friction="0.1"/>
		</joint>
		<link name="leg_l_link7">
	    	<collision>
				<origin xyz="0 0 0" rpy="0 0 0"/>
	    		<geometry>                                                              
					<mesh filename="package://ginko_description/meshes/stl/link07_l_toe02.stl"/>
	    		</geometry>
			</collision>
			<visual>
				<origin xyz="0 0 0" rpy="0 0 0"/>
				<geometry>
					<mesh filename="package://ginko_description/meshes/obj/link07_l_toe02.obj"/>
				</geometry>
			</visual>
			<inertial>
				<mass value="0.10920041"/>
				<origin xyz="0.02658756 0.00000053 -0.01782468" rpy="0 0 0"/>
				<inertia
					ixx="0.00003853"
					ixy="0.00000000" iyy="0.00005192"
					ixz="-0.00000479" iyz="0.00000000" izz="0.00003521"/>
			</inertial>
		</link>
		<joint name="leg_l_joint8" type="revolute">
			<parent link="leg_l_link7"/>
			<child  link="leg_l_link8"/>
			<origin xyz="0.0342 0 -0.04" rpy="0 0 0"/>
			<axis xyz="0 0 1"/>
			<limit effort="1000.0" lower="-2.6" upper="2.6" velocity="10.0"/>
			<dynamics damping="0.1" friction="0.1"/>
		</joint>
		<link name="leg_l_link8">
			<collision>
				<origin xyz="0 0 -0.003" rpy="0 0 0"/>
				<geometry>
					<box size="0.128 0.08 0.006"/>                                                    
				</geometry>
			</collision>
			<visual>
				<origin xyz="0 0 0" rpy="0 0 0"/>
				<geometry>
					<mesh filename="package://ginko_description/meshes/obj/link08_l_toe03.obj"/>
				</geometry>
			</visual>
			<inertial>
				<mass value="0.05363111"/>
				<origin xyz="0.00000000 0.00000000 -0.00269342" rpy="0 0 0"/>
				<inertia
					ixx="0.00002877"
					ixy="0.00000000" iyy="0.00007083"
					ixz="0.00000000" iyz="-0.00000000" izz="0.00009934"/>
			</inertial>
		</link>
	</xacro:macro>
</robot>
